2024-05-27 11:30:05,347 - ERROR - Exception on /graphql [OPTIONS]
Traceback (most recent call last):
  File "/home/dominic-source/Projects/venv/lib/python3.11/site-packages/flask/app.py", line 870, in full_dispatch_request
    rv = self.dispatch_request()
         ^^^^^^^^^^^^^^^^^^^^^^^
  File "/home/dominic-source/Projects/venv/lib/python3.11/site-packages/flask/app.py", line 844, in dispatch_request
    self.raise_routing_exception(req)
  File "/home/dominic-source/Projects/venv/lib/python3.11/site-packages/flask/app.py", line 453, in raise_routing_exception
    raise request.routing_exception  # type: ignore[misc]
    ^^^^^^^^^^^^^^^^^^^^^^^^^^^^^^^
  File "/home/dominic-source/Projects/venv/lib/python3.11/site-packages/flask/ctx.py", line 362, in match_request
    result = self.url_adapter.match(return_rule=True)  # type: ignore
             ^^^^^^^^^^^^^^^^^^^^^^^^^^^^^^^^^^^^^^^^
  File "/home/dominic-source/Projects/venv/lib/python3.11/site-packages/werkzeug/routing/map.py", line 624, in match
    raise NotFound() from None
werkzeug.exceptions.NotFound: 404 Not Found: The requested URL was not found on the server. If you entered the URL manually please check your spelling and try again.

During handling of the above exception, another exception occurred:

Traceback (most recent call last):
  File "/home/dominic-source/Projects/venv/lib/python3.11/site-packages/flask/app.py", line 1463, in wsgi_app
    response = self.full_dispatch_request()
               ^^^^^^^^^^^^^^^^^^^^^^^^^^^^
  File "/home/dominic-source/Projects/venv/lib/python3.11/site-packages/flask/app.py", line 872, in full_dispatch_request
    rv = self.handle_user_exception(e)
         ^^^^^^^^^^^^^^^^^^^^^^^^^^^^^
  File "/home/dominic-source/Projects/venv/lib/python3.11/site-packages/flask/app.py", line 755, in handle_user_exception
    return self.handle_http_exception(e)
           ^^^^^^^^^^^^^^^^^^^^^^^^^^^^^
  File "/home/dominic-source/Projects/venv/lib/python3.11/site-packages/flask/app.py", line 730, in handle_http_exception
    return self.ensure_sync(handler)(e)  # type: ignore[no-any-return]
           ^^^^^^^^^^^^^^^^^^^^^^^^^^^^
TypeError: page_not_found() takes 0 positional arguments but 1 was given
2024-05-27 11:30:37,353 - ERROR - Exception on /graphql [OPTIONS]
Traceback (most recent call last):
  File "/home/dominic-source/Projects/venv/lib/python3.11/site-packages/flask/app.py", line 870, in full_dispatch_request
    rv = self.dispatch_request()
         ^^^^^^^^^^^^^^^^^^^^^^^
  File "/home/dominic-source/Projects/venv/lib/python3.11/site-packages/flask/app.py", line 844, in dispatch_request
    self.raise_routing_exception(req)
  File "/home/dominic-source/Projects/venv/lib/python3.11/site-packages/flask/app.py", line 453, in raise_routing_exception
    raise request.routing_exception  # type: ignore[misc]
    ^^^^^^^^^^^^^^^^^^^^^^^^^^^^^^^
  File "/home/dominic-source/Projects/venv/lib/python3.11/site-packages/flask/ctx.py", line 362, in match_request
    result = self.url_adapter.match(return_rule=True)  # type: ignore
             ^^^^^^^^^^^^^^^^^^^^^^^^^^^^^^^^^^^^^^^^
  File "/home/dominic-source/Projects/venv/lib/python3.11/site-packages/werkzeug/routing/map.py", line 624, in match
    raise NotFound() from None
werkzeug.exceptions.NotFound: 404 Not Found: The requested URL was not found on the server. If you entered the URL manually please check your spelling and try again.

During handling of the above exception, another exception occurred:

Traceback (most recent call last):
  File "/home/dominic-source/Projects/venv/lib/python3.11/site-packages/flask/app.py", line 1463, in wsgi_app
    response = self.full_dispatch_request()
               ^^^^^^^^^^^^^^^^^^^^^^^^^^^^
  File "/home/dominic-source/Projects/venv/lib/python3.11/site-packages/flask/app.py", line 872, in full_dispatch_request
    rv = self.handle_user_exception(e)
         ^^^^^^^^^^^^^^^^^^^^^^^^^^^^^
  File "/home/dominic-source/Projects/venv/lib/python3.11/site-packages/flask/app.py", line 755, in handle_user_exception
    return self.handle_http_exception(e)
           ^^^^^^^^^^^^^^^^^^^^^^^^^^^^^
  File "/home/dominic-source/Projects/venv/lib/python3.11/site-packages/flask/app.py", line 730, in handle_http_exception
    return self.ensure_sync(handler)(e)  # type: ignore[no-any-return]
           ^^^^^^^^^^^^^^^^^^^^^^^^^^^^
TypeError: page_not_found() takes 0 positional arguments but 1 was given
2024-05-27 11:30:38,351 - ERROR - Exception on /graphql [OPTIONS]
Traceback (most recent call last):
  File "/home/dominic-source/Projects/venv/lib/python3.11/site-packages/flask/app.py", line 870, in full_dispatch_request
    rv = self.dispatch_request()
         ^^^^^^^^^^^^^^^^^^^^^^^
  File "/home/dominic-source/Projects/venv/lib/python3.11/site-packages/flask/app.py", line 844, in dispatch_request
    self.raise_routing_exception(req)
  File "/home/dominic-source/Projects/venv/lib/python3.11/site-packages/flask/app.py", line 453, in raise_routing_exception
    raise request.routing_exception  # type: ignore[misc]
    ^^^^^^^^^^^^^^^^^^^^^^^^^^^^^^^
  File "/home/dominic-source/Projects/venv/lib/python3.11/site-packages/flask/ctx.py", line 362, in match_request
    result = self.url_adapter.match(return_rule=True)  # type: ignore
             ^^^^^^^^^^^^^^^^^^^^^^^^^^^^^^^^^^^^^^^^
  File "/home/dominic-source/Projects/venv/lib/python3.11/site-packages/werkzeug/routing/map.py", line 624, in match
    raise NotFound() from None
werkzeug.exceptions.NotFound: 404 Not Found: The requested URL was not found on the server. If you entered the URL manually please check your spelling and try again.

During handling of the above exception, another exception occurred:

Traceback (most recent call last):
  File "/home/dominic-source/Projects/venv/lib/python3.11/site-packages/flask/app.py", line 1463, in wsgi_app
    response = self.full_dispatch_request()
               ^^^^^^^^^^^^^^^^^^^^^^^^^^^^
  File "/home/dominic-source/Projects/venv/lib/python3.11/site-packages/flask/app.py", line 872, in full_dispatch_request
    rv = self.handle_user_exception(e)
         ^^^^^^^^^^^^^^^^^^^^^^^^^^^^^
  File "/home/dominic-source/Projects/venv/lib/python3.11/site-packages/flask/app.py", line 755, in handle_user_exception
    return self.handle_http_exception(e)
           ^^^^^^^^^^^^^^^^^^^^^^^^^^^^^
  File "/home/dominic-source/Projects/venv/lib/python3.11/site-packages/flask/app.py", line 730, in handle_http_exception
    return self.ensure_sync(handler)(e)  # type: ignore[no-any-return]
           ^^^^^^^^^^^^^^^^^^^^^^^^^^^^
TypeError: page_not_found() takes 0 positional arguments but 1 was given
2024-05-27 11:30:39,351 - ERROR - Exception on /graphql [OPTIONS]
Traceback (most recent call last):
  File "/home/dominic-source/Projects/venv/lib/python3.11/site-packages/flask/app.py", line 870, in full_dispatch_request
    rv = self.dispatch_request()
         ^^^^^^^^^^^^^^^^^^^^^^^
  File "/home/dominic-source/Projects/venv/lib/python3.11/site-packages/flask/app.py", line 844, in dispatch_request
    self.raise_routing_exception(req)
  File "/home/dominic-source/Projects/venv/lib/python3.11/site-packages/flask/app.py", line 453, in raise_routing_exception
    raise request.routing_exception  # type: ignore[misc]
    ^^^^^^^^^^^^^^^^^^^^^^^^^^^^^^^
  File "/home/dominic-source/Projects/venv/lib/python3.11/site-packages/flask/ctx.py", line 362, in match_request
    result = self.url_adapter.match(return_rule=True)  # type: ignore
             ^^^^^^^^^^^^^^^^^^^^^^^^^^^^^^^^^^^^^^^^
  File "/home/dominic-source/Projects/venv/lib/python3.11/site-packages/werkzeug/routing/map.py", line 624, in match
    raise NotFound() from None
werkzeug.exceptions.NotFound: 404 Not Found: The requested URL was not found on the server. If you entered the URL manually please check your spelling and try again.

During handling of the above exception, another exception occurred:

Traceback (most recent call last):
  File "/home/dominic-source/Projects/venv/lib/python3.11/site-packages/flask/app.py", line 1463, in wsgi_app
    response = self.full_dispatch_request()
               ^^^^^^^^^^^^^^^^^^^^^^^^^^^^
  File "/home/dominic-source/Projects/venv/lib/python3.11/site-packages/flask/app.py", line 872, in full_dispatch_request
    rv = self.handle_user_exception(e)
         ^^^^^^^^^^^^^^^^^^^^^^^^^^^^^
  File "/home/dominic-source/Projects/venv/lib/python3.11/site-packages/flask/app.py", line 755, in handle_user_exception
    return self.handle_http_exception(e)
           ^^^^^^^^^^^^^^^^^^^^^^^^^^^^^
  File "/home/dominic-source/Projects/venv/lib/python3.11/site-packages/flask/app.py", line 730, in handle_http_exception
    return self.ensure_sync(handler)(e)  # type: ignore[no-any-return]
           ^^^^^^^^^^^^^^^^^^^^^^^^^^^^
TypeError: page_not_found() takes 0 positional arguments but 1 was given
2024-05-27 11:30:40,351 - ERROR - Exception on /graphql [OPTIONS]
Traceback (most recent call last):
  File "/home/dominic-source/Projects/venv/lib/python3.11/site-packages/flask/app.py", line 870, in full_dispatch_request
    rv = self.dispatch_request()
         ^^^^^^^^^^^^^^^^^^^^^^^
  File "/home/dominic-source/Projects/venv/lib/python3.11/site-packages/flask/app.py", line 844, in dispatch_request
    self.raise_routing_exception(req)
  File "/home/dominic-source/Projects/venv/lib/python3.11/site-packages/flask/app.py", line 453, in raise_routing_exception
    raise request.routing_exception  # type: ignore[misc]
    ^^^^^^^^^^^^^^^^^^^^^^^^^^^^^^^
  File "/home/dominic-source/Projects/venv/lib/python3.11/site-packages/flask/ctx.py", line 362, in match_request
    result = self.url_adapter.match(return_rule=True)  # type: ignore
             ^^^^^^^^^^^^^^^^^^^^^^^^^^^^^^^^^^^^^^^^
  File "/home/dominic-source/Projects/venv/lib/python3.11/site-packages/werkzeug/routing/map.py", line 624, in match
    raise NotFound() from None
werkzeug.exceptions.NotFound: 404 Not Found: The requested URL was not found on the server. If you entered the URL manually please check your spelling and try again.

During handling of the above exception, another exception occurred:

Traceback (most recent call last):
  File "/home/dominic-source/Projects/venv/lib/python3.11/site-packages/flask/app.py", line 1463, in wsgi_app
    response = self.full_dispatch_request()
               ^^^^^^^^^^^^^^^^^^^^^^^^^^^^
  File "/home/dominic-source/Projects/venv/lib/python3.11/site-packages/flask/app.py", line 872, in full_dispatch_request
    rv = self.handle_user_exception(e)
         ^^^^^^^^^^^^^^^^^^^^^^^^^^^^^
  File "/home/dominic-source/Projects/venv/lib/python3.11/site-packages/flask/app.py", line 755, in handle_user_exception
    return self.handle_http_exception(e)
           ^^^^^^^^^^^^^^^^^^^^^^^^^^^^^
  File "/home/dominic-source/Projects/venv/lib/python3.11/site-packages/flask/app.py", line 730, in handle_http_exception
    return self.ensure_sync(handler)(e)  # type: ignore[no-any-return]
           ^^^^^^^^^^^^^^^^^^^^^^^^^^^^
TypeError: page_not_found() takes 0 positional arguments but 1 was given
2024-05-27 11:30:41,351 - ERROR - Exception on /graphql [OPTIONS]
Traceback (most recent call last):
  File "/home/dominic-source/Projects/venv/lib/python3.11/site-packages/flask/app.py", line 870, in full_dispatch_request
    rv = self.dispatch_request()
         ^^^^^^^^^^^^^^^^^^^^^^^
  File "/home/dominic-source/Projects/venv/lib/python3.11/site-packages/flask/app.py", line 844, in dispatch_request
    self.raise_routing_exception(req)
  File "/home/dominic-source/Projects/venv/lib/python3.11/site-packages/flask/app.py", line 453, in raise_routing_exception
    raise request.routing_exception  # type: ignore[misc]
    ^^^^^^^^^^^^^^^^^^^^^^^^^^^^^^^
  File "/home/dominic-source/Projects/venv/lib/python3.11/site-packages/flask/ctx.py", line 362, in match_request
    result = self.url_adapter.match(return_rule=True)  # type: ignore
             ^^^^^^^^^^^^^^^^^^^^^^^^^^^^^^^^^^^^^^^^
  File "/home/dominic-source/Projects/venv/lib/python3.11/site-packages/werkzeug/routing/map.py", line 624, in match
    raise NotFound() from None
werkzeug.exceptions.NotFound: 404 Not Found: The requested URL was not found on the server. If you entered the URL manually please check your spelling and try again.

During handling of the above exception, another exception occurred:

Traceback (most recent call last):
  File "/home/dominic-source/Projects/venv/lib/python3.11/site-packages/flask/app.py", line 1463, in wsgi_app
    response = self.full_dispatch_request()
               ^^^^^^^^^^^^^^^^^^^^^^^^^^^^
  File "/home/dominic-source/Projects/venv/lib/python3.11/site-packages/flask/app.py", line 872, in full_dispatch_request
    rv = self.handle_user_exception(e)
         ^^^^^^^^^^^^^^^^^^^^^^^^^^^^^
  File "/home/dominic-source/Projects/venv/lib/python3.11/site-packages/flask/app.py", line 755, in handle_user_exception
    return self.handle_http_exception(e)
           ^^^^^^^^^^^^^^^^^^^^^^^^^^^^^
  File "/home/dominic-source/Projects/venv/lib/python3.11/site-packages/flask/app.py", line 730, in handle_http_exception
    return self.ensure_sync(handler)(e)  # type: ignore[no-any-return]
           ^^^^^^^^^^^^^^^^^^^^^^^^^^^^
TypeError: page_not_found() takes 0 positional arguments but 1 was given
2024-05-27 11:30:42,351 - ERROR - Exception on /graphql [OPTIONS]
Traceback (most recent call last):
  File "/home/dominic-source/Projects/venv/lib/python3.11/site-packages/flask/app.py", line 870, in full_dispatch_request
    rv = self.dispatch_request()
         ^^^^^^^^^^^^^^^^^^^^^^^
  File "/home/dominic-source/Projects/venv/lib/python3.11/site-packages/flask/app.py", line 844, in dispatch_request
    self.raise_routing_exception(req)
  File "/home/dominic-source/Projects/venv/lib/python3.11/site-packages/flask/app.py", line 453, in raise_routing_exception
    raise request.routing_exception  # type: ignore[misc]
    ^^^^^^^^^^^^^^^^^^^^^^^^^^^^^^^
  File "/home/dominic-source/Projects/venv/lib/python3.11/site-packages/flask/ctx.py", line 362, in match_request
    result = self.url_adapter.match(return_rule=True)  # type: ignore
             ^^^^^^^^^^^^^^^^^^^^^^^^^^^^^^^^^^^^^^^^
  File "/home/dominic-source/Projects/venv/lib/python3.11/site-packages/werkzeug/routing/map.py", line 624, in match
    raise NotFound() from None
werkzeug.exceptions.NotFound: 404 Not Found: The requested URL was not found on the server. If you entered the URL manually please check your spelling and try again.

During handling of the above exception, another exception occurred:

Traceback (most recent call last):
  File "/home/dominic-source/Projects/venv/lib/python3.11/site-packages/flask/app.py", line 1463, in wsgi_app
    response = self.full_dispatch_request()
               ^^^^^^^^^^^^^^^^^^^^^^^^^^^^
  File "/home/dominic-source/Projects/venv/lib/python3.11/site-packages/flask/app.py", line 872, in full_dispatch_request
    rv = self.handle_user_exception(e)
         ^^^^^^^^^^^^^^^^^^^^^^^^^^^^^
  File "/home/dominic-source/Projects/venv/lib/python3.11/site-packages/flask/app.py", line 755, in handle_user_exception
    return self.handle_http_exception(e)
           ^^^^^^^^^^^^^^^^^^^^^^^^^^^^^
  File "/home/dominic-source/Projects/venv/lib/python3.11/site-packages/flask/app.py", line 730, in handle_http_exception
    return self.ensure_sync(handler)(e)  # type: ignore[no-any-return]
           ^^^^^^^^^^^^^^^^^^^^^^^^^^^^
TypeError: page_not_found() takes 0 positional arguments but 1 was given
2024-05-27 11:30:43,351 - ERROR - Exception on /graphql [OPTIONS]
Traceback (most recent call last):
  File "/home/dominic-source/Projects/venv/lib/python3.11/site-packages/flask/app.py", line 870, in full_dispatch_request
    rv = self.dispatch_request()
         ^^^^^^^^^^^^^^^^^^^^^^^
  File "/home/dominic-source/Projects/venv/lib/python3.11/site-packages/flask/app.py", line 844, in dispatch_request
    self.raise_routing_exception(req)
  File "/home/dominic-source/Projects/venv/lib/python3.11/site-packages/flask/app.py", line 453, in raise_routing_exception
    raise request.routing_exception  # type: ignore[misc]
    ^^^^^^^^^^^^^^^^^^^^^^^^^^^^^^^
  File "/home/dominic-source/Projects/venv/lib/python3.11/site-packages/flask/ctx.py", line 362, in match_request
    result = self.url_adapter.match(return_rule=True)  # type: ignore
             ^^^^^^^^^^^^^^^^^^^^^^^^^^^^^^^^^^^^^^^^
  File "/home/dominic-source/Projects/venv/lib/python3.11/site-packages/werkzeug/routing/map.py", line 624, in match
    raise NotFound() from None
werkzeug.exceptions.NotFound: 404 Not Found: The requested URL was not found on the server. If you entered the URL manually please check your spelling and try again.

During handling of the above exception, another exception occurred:

Traceback (most recent call last):
  File "/home/dominic-source/Projects/venv/lib/python3.11/site-packages/flask/app.py", line 1463, in wsgi_app
    response = self.full_dispatch_request()
               ^^^^^^^^^^^^^^^^^^^^^^^^^^^^
  File "/home/dominic-source/Projects/venv/lib/python3.11/site-packages/flask/app.py", line 872, in full_dispatch_request
    rv = self.handle_user_exception(e)
         ^^^^^^^^^^^^^^^^^^^^^^^^^^^^^
  File "/home/dominic-source/Projects/venv/lib/python3.11/site-packages/flask/app.py", line 755, in handle_user_exception
    return self.handle_http_exception(e)
           ^^^^^^^^^^^^^^^^^^^^^^^^^^^^^
  File "/home/dominic-source/Projects/venv/lib/python3.11/site-packages/flask/app.py", line 730, in handle_http_exception
    return self.ensure_sync(handler)(e)  # type: ignore[no-any-return]
           ^^^^^^^^^^^^^^^^^^^^^^^^^^^^
TypeError: page_not_found() takes 0 positional arguments but 1 was given
2024-05-27 11:30:44,350 - ERROR - Exception on /graphql [OPTIONS]
Traceback (most recent call last):
  File "/home/dominic-source/Projects/venv/lib/python3.11/site-packages/flask/app.py", line 870, in full_dispatch_request
    rv = self.dispatch_request()
         ^^^^^^^^^^^^^^^^^^^^^^^
  File "/home/dominic-source/Projects/venv/lib/python3.11/site-packages/flask/app.py", line 844, in dispatch_request
    self.raise_routing_exception(req)
  File "/home/dominic-source/Projects/venv/lib/python3.11/site-packages/flask/app.py", line 453, in raise_routing_exception
    raise request.routing_exception  # type: ignore[misc]
    ^^^^^^^^^^^^^^^^^^^^^^^^^^^^^^^
  File "/home/dominic-source/Projects/venv/lib/python3.11/site-packages/flask/ctx.py", line 362, in match_request
    result = self.url_adapter.match(return_rule=True)  # type: ignore
             ^^^^^^^^^^^^^^^^^^^^^^^^^^^^^^^^^^^^^^^^
  File "/home/dominic-source/Projects/venv/lib/python3.11/site-packages/werkzeug/routing/map.py", line 624, in match
    raise NotFound() from None
werkzeug.exceptions.NotFound: 404 Not Found: The requested URL was not found on the server. If you entered the URL manually please check your spelling and try again.

During handling of the above exception, another exception occurred:

Traceback (most recent call last):
  File "/home/dominic-source/Projects/venv/lib/python3.11/site-packages/flask/app.py", line 1463, in wsgi_app
    response = self.full_dispatch_request()
               ^^^^^^^^^^^^^^^^^^^^^^^^^^^^
  File "/home/dominic-source/Projects/venv/lib/python3.11/site-packages/flask/app.py", line 872, in full_dispatch_request
    rv = self.handle_user_exception(e)
         ^^^^^^^^^^^^^^^^^^^^^^^^^^^^^
  File "/home/dominic-source/Projects/venv/lib/python3.11/site-packages/flask/app.py", line 755, in handle_user_exception
    return self.handle_http_exception(e)
           ^^^^^^^^^^^^^^^^^^^^^^^^^^^^^
  File "/home/dominic-source/Projects/venv/lib/python3.11/site-packages/flask/app.py", line 730, in handle_http_exception
    return self.ensure_sync(handler)(e)  # type: ignore[no-any-return]
           ^^^^^^^^^^^^^^^^^^^^^^^^^^^^
TypeError: page_not_found() takes 0 positional arguments but 1 was given
2024-05-27 11:30:45,350 - ERROR - Exception on /graphql [OPTIONS]
Traceback (most recent call last):
  File "/home/dominic-source/Projects/venv/lib/python3.11/site-packages/flask/app.py", line 870, in full_dispatch_request
    rv = self.dispatch_request()
         ^^^^^^^^^^^^^^^^^^^^^^^
  File "/home/dominic-source/Projects/venv/lib/python3.11/site-packages/flask/app.py", line 844, in dispatch_request
    self.raise_routing_exception(req)
  File "/home/dominic-source/Projects/venv/lib/python3.11/site-packages/flask/app.py", line 453, in raise_routing_exception
    raise request.routing_exception  # type: ignore[misc]
    ^^^^^^^^^^^^^^^^^^^^^^^^^^^^^^^
  File "/home/dominic-source/Projects/venv/lib/python3.11/site-packages/flask/ctx.py", line 362, in match_request
    result = self.url_adapter.match(return_rule=True)  # type: ignore
             ^^^^^^^^^^^^^^^^^^^^^^^^^^^^^^^^^^^^^^^^
  File "/home/dominic-source/Projects/venv/lib/python3.11/site-packages/werkzeug/routing/map.py", line 624, in match
    raise NotFound() from None
werkzeug.exceptions.NotFound: 404 Not Found: The requested URL was not found on the server. If you entered the URL manually please check your spelling and try again.

During handling of the above exception, another exception occurred:

Traceback (most recent call last):
  File "/home/dominic-source/Projects/venv/lib/python3.11/site-packages/flask/app.py", line 1463, in wsgi_app
    response = self.full_dispatch_request()
               ^^^^^^^^^^^^^^^^^^^^^^^^^^^^
  File "/home/dominic-source/Projects/venv/lib/python3.11/site-packages/flask/app.py", line 872, in full_dispatch_request
    rv = self.handle_user_exception(e)
         ^^^^^^^^^^^^^^^^^^^^^^^^^^^^^
  File "/home/dominic-source/Projects/venv/lib/python3.11/site-packages/flask/app.py", line 755, in handle_user_exception
    return self.handle_http_exception(e)
           ^^^^^^^^^^^^^^^^^^^^^^^^^^^^^
  File "/home/dominic-source/Projects/venv/lib/python3.11/site-packages/flask/app.py", line 730, in handle_http_exception
    return self.ensure_sync(handler)(e)  # type: ignore[no-any-return]
           ^^^^^^^^^^^^^^^^^^^^^^^^^^^^
TypeError: page_not_found() takes 0 positional arguments but 1 was given
2024-05-27 11:30:46,350 - ERROR - Exception on /graphql [OPTIONS]
Traceback (most recent call last):
  File "/home/dominic-source/Projects/venv/lib/python3.11/site-packages/flask/app.py", line 870, in full_dispatch_request
    rv = self.dispatch_request()
         ^^^^^^^^^^^^^^^^^^^^^^^
  File "/home/dominic-source/Projects/venv/lib/python3.11/site-packages/flask/app.py", line 844, in dispatch_request
    self.raise_routing_exception(req)
  File "/home/dominic-source/Projects/venv/lib/python3.11/site-packages/flask/app.py", line 453, in raise_routing_exception
    raise request.routing_exception  # type: ignore[misc]
    ^^^^^^^^^^^^^^^^^^^^^^^^^^^^^^^
  File "/home/dominic-source/Projects/venv/lib/python3.11/site-packages/flask/ctx.py", line 362, in match_request
    result = self.url_adapter.match(return_rule=True)  # type: ignore
             ^^^^^^^^^^^^^^^^^^^^^^^^^^^^^^^^^^^^^^^^
  File "/home/dominic-source/Projects/venv/lib/python3.11/site-packages/werkzeug/routing/map.py", line 624, in match
    raise NotFound() from None
werkzeug.exceptions.NotFound: 404 Not Found: The requested URL was not found on the server. If you entered the URL manually please check your spelling and try again.

During handling of the above exception, another exception occurred:

Traceback (most recent call last):
  File "/home/dominic-source/Projects/venv/lib/python3.11/site-packages/flask/app.py", line 1463, in wsgi_app
    response = self.full_dispatch_request()
               ^^^^^^^^^^^^^^^^^^^^^^^^^^^^
  File "/home/dominic-source/Projects/venv/lib/python3.11/site-packages/flask/app.py", line 872, in full_dispatch_request
    rv = self.handle_user_exception(e)
         ^^^^^^^^^^^^^^^^^^^^^^^^^^^^^
  File "/home/dominic-source/Projects/venv/lib/python3.11/site-packages/flask/app.py", line 755, in handle_user_exception
    return self.handle_http_exception(e)
           ^^^^^^^^^^^^^^^^^^^^^^^^^^^^^
  File "/home/dominic-source/Projects/venv/lib/python3.11/site-packages/flask/app.py", line 730, in handle_http_exception
    return self.ensure_sync(handler)(e)  # type: ignore[no-any-return]
           ^^^^^^^^^^^^^^^^^^^^^^^^^^^^
TypeError: page_not_found() takes 0 positional arguments but 1 was given
2024-05-27 11:30:47,350 - ERROR - Exception on /graphql [OPTIONS]
Traceback (most recent call last):
  File "/home/dominic-source/Projects/venv/lib/python3.11/site-packages/flask/app.py", line 870, in full_dispatch_request
    rv = self.dispatch_request()
         ^^^^^^^^^^^^^^^^^^^^^^^
  File "/home/dominic-source/Projects/venv/lib/python3.11/site-packages/flask/app.py", line 844, in dispatch_request
    self.raise_routing_exception(req)
  File "/home/dominic-source/Projects/venv/lib/python3.11/site-packages/flask/app.py", line 453, in raise_routing_exception
    raise request.routing_exception  # type: ignore[misc]
    ^^^^^^^^^^^^^^^^^^^^^^^^^^^^^^^
  File "/home/dominic-source/Projects/venv/lib/python3.11/site-packages/flask/ctx.py", line 362, in match_request
    result = self.url_adapter.match(return_rule=True)  # type: ignore
             ^^^^^^^^^^^^^^^^^^^^^^^^^^^^^^^^^^^^^^^^
  File "/home/dominic-source/Projects/venv/lib/python3.11/site-packages/werkzeug/routing/map.py", line 624, in match
    raise NotFound() from None
werkzeug.exceptions.NotFound: 404 Not Found: The requested URL was not found on the server. If you entered the URL manually please check your spelling and try again.

During handling of the above exception, another exception occurred:

Traceback (most recent call last):
  File "/home/dominic-source/Projects/venv/lib/python3.11/site-packages/flask/app.py", line 1463, in wsgi_app
    response = self.full_dispatch_request()
               ^^^^^^^^^^^^^^^^^^^^^^^^^^^^
  File "/home/dominic-source/Projects/venv/lib/python3.11/site-packages/flask/app.py", line 872, in full_dispatch_request
    rv = self.handle_user_exception(e)
         ^^^^^^^^^^^^^^^^^^^^^^^^^^^^^
  File "/home/dominic-source/Projects/venv/lib/python3.11/site-packages/flask/app.py", line 755, in handle_user_exception
    return self.handle_http_exception(e)
           ^^^^^^^^^^^^^^^^^^^^^^^^^^^^^
  File "/home/dominic-source/Projects/venv/lib/python3.11/site-packages/flask/app.py", line 730, in handle_http_exception
    return self.ensure_sync(handler)(e)  # type: ignore[no-any-return]
           ^^^^^^^^^^^^^^^^^^^^^^^^^^^^
TypeError: page_not_found() takes 0 positional arguments but 1 was given
2024-05-27 11:30:48,350 - ERROR - Exception on /graphql [OPTIONS]
Traceback (most recent call last):
  File "/home/dominic-source/Projects/venv/lib/python3.11/site-packages/flask/app.py", line 870, in full_dispatch_request
    rv = self.dispatch_request()
         ^^^^^^^^^^^^^^^^^^^^^^^
  File "/home/dominic-source/Projects/venv/lib/python3.11/site-packages/flask/app.py", line 844, in dispatch_request
    self.raise_routing_exception(req)
  File "/home/dominic-source/Projects/venv/lib/python3.11/site-packages/flask/app.py", line 453, in raise_routing_exception
    raise request.routing_exception  # type: ignore[misc]
    ^^^^^^^^^^^^^^^^^^^^^^^^^^^^^^^
  File "/home/dominic-source/Projects/venv/lib/python3.11/site-packages/flask/ctx.py", line 362, in match_request
    result = self.url_adapter.match(return_rule=True)  # type: ignore
             ^^^^^^^^^^^^^^^^^^^^^^^^^^^^^^^^^^^^^^^^
  File "/home/dominic-source/Projects/venv/lib/python3.11/site-packages/werkzeug/routing/map.py", line 624, in match
    raise NotFound() from None
werkzeug.exceptions.NotFound: 404 Not Found: The requested URL was not found on the server. If you entered the URL manually please check your spelling and try again.

During handling of the above exception, another exception occurred:

Traceback (most recent call last):
  File "/home/dominic-source/Projects/venv/lib/python3.11/site-packages/flask/app.py", line 1463, in wsgi_app
    response = self.full_dispatch_request()
               ^^^^^^^^^^^^^^^^^^^^^^^^^^^^
  File "/home/dominic-source/Projects/venv/lib/python3.11/site-packages/flask/app.py", line 872, in full_dispatch_request
    rv = self.handle_user_exception(e)
         ^^^^^^^^^^^^^^^^^^^^^^^^^^^^^
  File "/home/dominic-source/Projects/venv/lib/python3.11/site-packages/flask/app.py", line 755, in handle_user_exception
    return self.handle_http_exception(e)
           ^^^^^^^^^^^^^^^^^^^^^^^^^^^^^
  File "/home/dominic-source/Projects/venv/lib/python3.11/site-packages/flask/app.py", line 730, in handle_http_exception
    return self.ensure_sync(handler)(e)  # type: ignore[no-any-return]
           ^^^^^^^^^^^^^^^^^^^^^^^^^^^^
TypeError: page_not_found() takes 0 positional arguments but 1 was given
2024-05-27 11:30:49,356 - ERROR - Exception on /graphql [OPTIONS]
Traceback (most recent call last):
  File "/home/dominic-source/Projects/venv/lib/python3.11/site-packages/flask/app.py", line 870, in full_dispatch_request
    rv = self.dispatch_request()
         ^^^^^^^^^^^^^^^^^^^^^^^
  File "/home/dominic-source/Projects/venv/lib/python3.11/site-packages/flask/app.py", line 844, in dispatch_request
    self.raise_routing_exception(req)
  File "/home/dominic-source/Projects/venv/lib/python3.11/site-packages/flask/app.py", line 453, in raise_routing_exception
    raise request.routing_exception  # type: ignore[misc]
    ^^^^^^^^^^^^^^^^^^^^^^^^^^^^^^^
  File "/home/dominic-source/Projects/venv/lib/python3.11/site-packages/flask/ctx.py", line 362, in match_request
    result = self.url_adapter.match(return_rule=True)  # type: ignore
             ^^^^^^^^^^^^^^^^^^^^^^^^^^^^^^^^^^^^^^^^
  File "/home/dominic-source/Projects/venv/lib/python3.11/site-packages/werkzeug/routing/map.py", line 624, in match
    raise NotFound() from None
werkzeug.exceptions.NotFound: 404 Not Found: The requested URL was not found on the server. If you entered the URL manually please check your spelling and try again.

During handling of the above exception, another exception occurred:

Traceback (most recent call last):
  File "/home/dominic-source/Projects/venv/lib/python3.11/site-packages/flask/app.py", line 1463, in wsgi_app
    response = self.full_dispatch_request()
               ^^^^^^^^^^^^^^^^^^^^^^^^^^^^
  File "/home/dominic-source/Projects/venv/lib/python3.11/site-packages/flask/app.py", line 872, in full_dispatch_request
    rv = self.handle_user_exception(e)
         ^^^^^^^^^^^^^^^^^^^^^^^^^^^^^
  File "/home/dominic-source/Projects/venv/lib/python3.11/site-packages/flask/app.py", line 755, in handle_user_exception
    return self.handle_http_exception(e)
           ^^^^^^^^^^^^^^^^^^^^^^^^^^^^^
  File "/home/dominic-source/Projects/venv/lib/python3.11/site-packages/flask/app.py", line 730, in handle_http_exception
    return self.ensure_sync(handler)(e)  # type: ignore[no-any-return]
           ^^^^^^^^^^^^^^^^^^^^^^^^^^^^
TypeError: page_not_found() takes 0 positional arguments but 1 was given
2024-05-27 11:30:50,352 - ERROR - Exception on /graphql [OPTIONS]
Traceback (most recent call last):
  File "/home/dominic-source/Projects/venv/lib/python3.11/site-packages/flask/app.py", line 870, in full_dispatch_request
    rv = self.dispatch_request()
         ^^^^^^^^^^^^^^^^^^^^^^^
  File "/home/dominic-source/Projects/venv/lib/python3.11/site-packages/flask/app.py", line 844, in dispatch_request
    self.raise_routing_exception(req)
  File "/home/dominic-source/Projects/venv/lib/python3.11/site-packages/flask/app.py", line 453, in raise_routing_exception
    raise request.routing_exception  # type: ignore[misc]
    ^^^^^^^^^^^^^^^^^^^^^^^^^^^^^^^
  File "/home/dominic-source/Projects/venv/lib/python3.11/site-packages/flask/ctx.py", line 362, in match_request
    result = self.url_adapter.match(return_rule=True)  # type: ignore
             ^^^^^^^^^^^^^^^^^^^^^^^^^^^^^^^^^^^^^^^^
  File "/home/dominic-source/Projects/venv/lib/python3.11/site-packages/werkzeug/routing/map.py", line 624, in match
    raise NotFound() from None
werkzeug.exceptions.NotFound: 404 Not Found: The requested URL was not found on the server. If you entered the URL manually please check your spelling and try again.

During handling of the above exception, another exception occurred:

Traceback (most recent call last):
  File "/home/dominic-source/Projects/venv/lib/python3.11/site-packages/flask/app.py", line 1463, in wsgi_app
    response = self.full_dispatch_request()
               ^^^^^^^^^^^^^^^^^^^^^^^^^^^^
  File "/home/dominic-source/Projects/venv/lib/python3.11/site-packages/flask/app.py", line 872, in full_dispatch_request
    rv = self.handle_user_exception(e)
         ^^^^^^^^^^^^^^^^^^^^^^^^^^^^^
  File "/home/dominic-source/Projects/venv/lib/python3.11/site-packages/flask/app.py", line 755, in handle_user_exception
    return self.handle_http_exception(e)
           ^^^^^^^^^^^^^^^^^^^^^^^^^^^^^
  File "/home/dominic-source/Projects/venv/lib/python3.11/site-packages/flask/app.py", line 730, in handle_http_exception
    return self.ensure_sync(handler)(e)  # type: ignore[no-any-return]
           ^^^^^^^^^^^^^^^^^^^^^^^^^^^^
TypeError: page_not_found() takes 0 positional arguments but 1 was given
2024-05-27 11:30:51,355 - ERROR - Exception on /graphql [OPTIONS]
Traceback (most recent call last):
  File "/home/dominic-source/Projects/venv/lib/python3.11/site-packages/flask/app.py", line 870, in full_dispatch_request
    rv = self.dispatch_request()
         ^^^^^^^^^^^^^^^^^^^^^^^
  File "/home/dominic-source/Projects/venv/lib/python3.11/site-packages/flask/app.py", line 844, in dispatch_request
    self.raise_routing_exception(req)
  File "/home/dominic-source/Projects/venv/lib/python3.11/site-packages/flask/app.py", line 453, in raise_routing_exception
    raise request.routing_exception  # type: ignore[misc]
    ^^^^^^^^^^^^^^^^^^^^^^^^^^^^^^^
  File "/home/dominic-source/Projects/venv/lib/python3.11/site-packages/flask/ctx.py", line 362, in match_request
    result = self.url_adapter.match(return_rule=True)  # type: ignore
             ^^^^^^^^^^^^^^^^^^^^^^^^^^^^^^^^^^^^^^^^
  File "/home/dominic-source/Projects/venv/lib/python3.11/site-packages/werkzeug/routing/map.py", line 624, in match
    raise NotFound() from None
werkzeug.exceptions.NotFound: 404 Not Found: The requested URL was not found on the server. If you entered the URL manually please check your spelling and try again.

During handling of the above exception, another exception occurred:

Traceback (most recent call last):
  File "/home/dominic-source/Projects/venv/lib/python3.11/site-packages/flask/app.py", line 1463, in wsgi_app
    response = self.full_dispatch_request()
               ^^^^^^^^^^^^^^^^^^^^^^^^^^^^
  File "/home/dominic-source/Projects/venv/lib/python3.11/site-packages/flask/app.py", line 872, in full_dispatch_request
    rv = self.handle_user_exception(e)
         ^^^^^^^^^^^^^^^^^^^^^^^^^^^^^
  File "/home/dominic-source/Projects/venv/lib/python3.11/site-packages/flask/app.py", line 755, in handle_user_exception
    return self.handle_http_exception(e)
           ^^^^^^^^^^^^^^^^^^^^^^^^^^^^^
  File "/home/dominic-source/Projects/venv/lib/python3.11/site-packages/flask/app.py", line 730, in handle_http_exception
    return self.ensure_sync(handler)(e)  # type: ignore[no-any-return]
           ^^^^^^^^^^^^^^^^^^^^^^^^^^^^
TypeError: page_not_found() takes 0 positional arguments but 1 was given
2024-05-27 11:30:52,349 - ERROR - Exception on /graphql [OPTIONS]
Traceback (most recent call last):
  File "/home/dominic-source/Projects/venv/lib/python3.11/site-packages/flask/app.py", line 870, in full_dispatch_request
    rv = self.dispatch_request()
         ^^^^^^^^^^^^^^^^^^^^^^^
  File "/home/dominic-source/Projects/venv/lib/python3.11/site-packages/flask/app.py", line 844, in dispatch_request
    self.raise_routing_exception(req)
  File "/home/dominic-source/Projects/venv/lib/python3.11/site-packages/flask/app.py", line 453, in raise_routing_exception
    raise request.routing_exception  # type: ignore[misc]
    ^^^^^^^^^^^^^^^^^^^^^^^^^^^^^^^
  File "/home/dominic-source/Projects/venv/lib/python3.11/site-packages/flask/ctx.py", line 362, in match_request
    result = self.url_adapter.match(return_rule=True)  # type: ignore
             ^^^^^^^^^^^^^^^^^^^^^^^^^^^^^^^^^^^^^^^^
  File "/home/dominic-source/Projects/venv/lib/python3.11/site-packages/werkzeug/routing/map.py", line 624, in match
    raise NotFound() from None
werkzeug.exceptions.NotFound: 404 Not Found: The requested URL was not found on the server. If you entered the URL manually please check your spelling and try again.

During handling of the above exception, another exception occurred:

Traceback (most recent call last):
  File "/home/dominic-source/Projects/venv/lib/python3.11/site-packages/flask/app.py", line 1463, in wsgi_app
    response = self.full_dispatch_request()
               ^^^^^^^^^^^^^^^^^^^^^^^^^^^^
  File "/home/dominic-source/Projects/venv/lib/python3.11/site-packages/flask/app.py", line 872, in full_dispatch_request
    rv = self.handle_user_exception(e)
         ^^^^^^^^^^^^^^^^^^^^^^^^^^^^^
  File "/home/dominic-source/Projects/venv/lib/python3.11/site-packages/flask/app.py", line 755, in handle_user_exception
    return self.handle_http_exception(e)
           ^^^^^^^^^^^^^^^^^^^^^^^^^^^^^
  File "/home/dominic-source/Projects/venv/lib/python3.11/site-packages/flask/app.py", line 730, in handle_http_exception
    return self.ensure_sync(handler)(e)  # type: ignore[no-any-return]
           ^^^^^^^^^^^^^^^^^^^^^^^^^^^^
TypeError: page_not_found() takes 0 positional arguments but 1 was given
2024-05-27 11:30:53,351 - ERROR - Exception on /graphql [OPTIONS]
Traceback (most recent call last):
  File "/home/dominic-source/Projects/venv/lib/python3.11/site-packages/flask/app.py", line 870, in full_dispatch_request
    rv = self.dispatch_request()
         ^^^^^^^^^^^^^^^^^^^^^^^
  File "/home/dominic-source/Projects/venv/lib/python3.11/site-packages/flask/app.py", line 844, in dispatch_request
    self.raise_routing_exception(req)
  File "/home/dominic-source/Projects/venv/lib/python3.11/site-packages/flask/app.py", line 453, in raise_routing_exception
    raise request.routing_exception  # type: ignore[misc]
    ^^^^^^^^^^^^^^^^^^^^^^^^^^^^^^^
  File "/home/dominic-source/Projects/venv/lib/python3.11/site-packages/flask/ctx.py", line 362, in match_request
    result = self.url_adapter.match(return_rule=True)  # type: ignore
             ^^^^^^^^^^^^^^^^^^^^^^^^^^^^^^^^^^^^^^^^
  File "/home/dominic-source/Projects/venv/lib/python3.11/site-packages/werkzeug/routing/map.py", line 624, in match
    raise NotFound() from None
werkzeug.exceptions.NotFound: 404 Not Found: The requested URL was not found on the server. If you entered the URL manually please check your spelling and try again.

During handling of the above exception, another exception occurred:

Traceback (most recent call last):
  File "/home/dominic-source/Projects/venv/lib/python3.11/site-packages/flask/app.py", line 1463, in wsgi_app
    response = self.full_dispatch_request()
               ^^^^^^^^^^^^^^^^^^^^^^^^^^^^
  File "/home/dominic-source/Projects/venv/lib/python3.11/site-packages/flask/app.py", line 872, in full_dispatch_request
    rv = self.handle_user_exception(e)
         ^^^^^^^^^^^^^^^^^^^^^^^^^^^^^
  File "/home/dominic-source/Projects/venv/lib/python3.11/site-packages/flask/app.py", line 755, in handle_user_exception
    return self.handle_http_exception(e)
           ^^^^^^^^^^^^^^^^^^^^^^^^^^^^^
  File "/home/dominic-source/Projects/venv/lib/python3.11/site-packages/flask/app.py", line 730, in handle_http_exception
    return self.ensure_sync(handler)(e)  # type: ignore[no-any-return]
           ^^^^^^^^^^^^^^^^^^^^^^^^^^^^
TypeError: page_not_found() takes 0 positional arguments but 1 was given
2024-05-27 11:30:54,353 - ERROR - Exception on /graphql [OPTIONS]
Traceback (most recent call last):
  File "/home/dominic-source/Projects/venv/lib/python3.11/site-packages/flask/app.py", line 870, in full_dispatch_request
    rv = self.dispatch_request()
         ^^^^^^^^^^^^^^^^^^^^^^^
  File "/home/dominic-source/Projects/venv/lib/python3.11/site-packages/flask/app.py", line 844, in dispatch_request
    self.raise_routing_exception(req)
  File "/home/dominic-source/Projects/venv/lib/python3.11/site-packages/flask/app.py", line 453, in raise_routing_exception
    raise request.routing_exception  # type: ignore[misc]
    ^^^^^^^^^^^^^^^^^^^^^^^^^^^^^^^
  File "/home/dominic-source/Projects/venv/lib/python3.11/site-packages/flask/ctx.py", line 362, in match_request
    result = self.url_adapter.match(return_rule=True)  # type: ignore
             ^^^^^^^^^^^^^^^^^^^^^^^^^^^^^^^^^^^^^^^^
  File "/home/dominic-source/Projects/venv/lib/python3.11/site-packages/werkzeug/routing/map.py", line 624, in match
    raise NotFound() from None
werkzeug.exceptions.NotFound: 404 Not Found: The requested URL was not found on the server. If you entered the URL manually please check your spelling and try again.

During handling of the above exception, another exception occurred:

Traceback (most recent call last):
  File "/home/dominic-source/Projects/venv/lib/python3.11/site-packages/flask/app.py", line 1463, in wsgi_app
    response = self.full_dispatch_request()
               ^^^^^^^^^^^^^^^^^^^^^^^^^^^^
  File "/home/dominic-source/Projects/venv/lib/python3.11/site-packages/flask/app.py", line 872, in full_dispatch_request
    rv = self.handle_user_exception(e)
         ^^^^^^^^^^^^^^^^^^^^^^^^^^^^^
  File "/home/dominic-source/Projects/venv/lib/python3.11/site-packages/flask/app.py", line 755, in handle_user_exception
    return self.handle_http_exception(e)
           ^^^^^^^^^^^^^^^^^^^^^^^^^^^^^
  File "/home/dominic-source/Projects/venv/lib/python3.11/site-packages/flask/app.py", line 730, in handle_http_exception
    return self.ensure_sync(handler)(e)  # type: ignore[no-any-return]
           ^^^^^^^^^^^^^^^^^^^^^^^^^^^^
TypeError: page_not_found() takes 0 positional arguments but 1 was given
2024-05-27 11:30:55,354 - ERROR - Exception on /graphql [OPTIONS]
Traceback (most recent call last):
  File "/home/dominic-source/Projects/venv/lib/python3.11/site-packages/flask/app.py", line 870, in full_dispatch_request
    rv = self.dispatch_request()
         ^^^^^^^^^^^^^^^^^^^^^^^
  File "/home/dominic-source/Projects/venv/lib/python3.11/site-packages/flask/app.py", line 844, in dispatch_request
    self.raise_routing_exception(req)
  File "/home/dominic-source/Projects/venv/lib/python3.11/site-packages/flask/app.py", line 453, in raise_routing_exception
    raise request.routing_exception  # type: ignore[misc]
    ^^^^^^^^^^^^^^^^^^^^^^^^^^^^^^^
  File "/home/dominic-source/Projects/venv/lib/python3.11/site-packages/flask/ctx.py", line 362, in match_request
    result = self.url_adapter.match(return_rule=True)  # type: ignore
             ^^^^^^^^^^^^^^^^^^^^^^^^^^^^^^^^^^^^^^^^
  File "/home/dominic-source/Projects/venv/lib/python3.11/site-packages/werkzeug/routing/map.py", line 624, in match
    raise NotFound() from None
werkzeug.exceptions.NotFound: 404 Not Found: The requested URL was not found on the server. If you entered the URL manually please check your spelling and try again.

During handling of the above exception, another exception occurred:

Traceback (most recent call last):
  File "/home/dominic-source/Projects/venv/lib/python3.11/site-packages/flask/app.py", line 1463, in wsgi_app
    response = self.full_dispatch_request()
               ^^^^^^^^^^^^^^^^^^^^^^^^^^^^
  File "/home/dominic-source/Projects/venv/lib/python3.11/site-packages/flask/app.py", line 872, in full_dispatch_request
    rv = self.handle_user_exception(e)
         ^^^^^^^^^^^^^^^^^^^^^^^^^^^^^
  File "/home/dominic-source/Projects/venv/lib/python3.11/site-packages/flask/app.py", line 755, in handle_user_exception
    return self.handle_http_exception(e)
           ^^^^^^^^^^^^^^^^^^^^^^^^^^^^^
  File "/home/dominic-source/Projects/venv/lib/python3.11/site-packages/flask/app.py", line 730, in handle_http_exception
    return self.ensure_sync(handler)(e)  # type: ignore[no-any-return]
           ^^^^^^^^^^^^^^^^^^^^^^^^^^^^
TypeError: page_not_found() takes 0 positional arguments but 1 was given
2024-05-27 11:30:56,348 - ERROR - Exception on /graphql [OPTIONS]
Traceback (most recent call last):
  File "/home/dominic-source/Projects/venv/lib/python3.11/site-packages/flask/app.py", line 870, in full_dispatch_request
    rv = self.dispatch_request()
         ^^^^^^^^^^^^^^^^^^^^^^^
  File "/home/dominic-source/Projects/venv/lib/python3.11/site-packages/flask/app.py", line 844, in dispatch_request
    self.raise_routing_exception(req)
  File "/home/dominic-source/Projects/venv/lib/python3.11/site-packages/flask/app.py", line 453, in raise_routing_exception
    raise request.routing_exception  # type: ignore[misc]
    ^^^^^^^^^^^^^^^^^^^^^^^^^^^^^^^
  File "/home/dominic-source/Projects/venv/lib/python3.11/site-packages/flask/ctx.py", line 362, in match_request
    result = self.url_adapter.match(return_rule=True)  # type: ignore
             ^^^^^^^^^^^^^^^^^^^^^^^^^^^^^^^^^^^^^^^^
  File "/home/dominic-source/Projects/venv/lib/python3.11/site-packages/werkzeug/routing/map.py", line 624, in match
    raise NotFound() from None
werkzeug.exceptions.NotFound: 404 Not Found: The requested URL was not found on the server. If you entered the URL manually please check your spelling and try again.

During handling of the above exception, another exception occurred:

Traceback (most recent call last):
  File "/home/dominic-source/Projects/venv/lib/python3.11/site-packages/flask/app.py", line 1463, in wsgi_app
    response = self.full_dispatch_request()
               ^^^^^^^^^^^^^^^^^^^^^^^^^^^^
  File "/home/dominic-source/Projects/venv/lib/python3.11/site-packages/flask/app.py", line 872, in full_dispatch_request
    rv = self.handle_user_exception(e)
         ^^^^^^^^^^^^^^^^^^^^^^^^^^^^^
  File "/home/dominic-source/Projects/venv/lib/python3.11/site-packages/flask/app.py", line 755, in handle_user_exception
    return self.handle_http_exception(e)
           ^^^^^^^^^^^^^^^^^^^^^^^^^^^^^
  File "/home/dominic-source/Projects/venv/lib/python3.11/site-packages/flask/app.py", line 730, in handle_http_exception
    return self.ensure_sync(handler)(e)  # type: ignore[no-any-return]
           ^^^^^^^^^^^^^^^^^^^^^^^^^^^^
TypeError: page_not_found() takes 0 positional arguments but 1 was given
2024-05-27 11:30:57,356 - ERROR - Exception on /graphql [OPTIONS]
Traceback (most recent call last):
  File "/home/dominic-source/Projects/venv/lib/python3.11/site-packages/flask/app.py", line 870, in full_dispatch_request
    rv = self.dispatch_request()
         ^^^^^^^^^^^^^^^^^^^^^^^
  File "/home/dominic-source/Projects/venv/lib/python3.11/site-packages/flask/app.py", line 844, in dispatch_request
    self.raise_routing_exception(req)
  File "/home/dominic-source/Projects/venv/lib/python3.11/site-packages/flask/app.py", line 453, in raise_routing_exception
    raise request.routing_exception  # type: ignore[misc]
    ^^^^^^^^^^^^^^^^^^^^^^^^^^^^^^^
  File "/home/dominic-source/Projects/venv/lib/python3.11/site-packages/flask/ctx.py", line 362, in match_request
    result = self.url_adapter.match(return_rule=True)  # type: ignore
             ^^^^^^^^^^^^^^^^^^^^^^^^^^^^^^^^^^^^^^^^
  File "/home/dominic-source/Projects/venv/lib/python3.11/site-packages/werkzeug/routing/map.py", line 624, in match
    raise NotFound() from None
werkzeug.exceptions.NotFound: 404 Not Found: The requested URL was not found on the server. If you entered the URL manually please check your spelling and try again.

During handling of the above exception, another exception occurred:

Traceback (most recent call last):
  File "/home/dominic-source/Projects/venv/lib/python3.11/site-packages/flask/app.py", line 1463, in wsgi_app
    response = self.full_dispatch_request()
               ^^^^^^^^^^^^^^^^^^^^^^^^^^^^
  File "/home/dominic-source/Projects/venv/lib/python3.11/site-packages/flask/app.py", line 872, in full_dispatch_request
    rv = self.handle_user_exception(e)
         ^^^^^^^^^^^^^^^^^^^^^^^^^^^^^
  File "/home/dominic-source/Projects/venv/lib/python3.11/site-packages/flask/app.py", line 755, in handle_user_exception
    return self.handle_http_exception(e)
           ^^^^^^^^^^^^^^^^^^^^^^^^^^^^^
  File "/home/dominic-source/Projects/venv/lib/python3.11/site-packages/flask/app.py", line 730, in handle_http_exception
    return self.ensure_sync(handler)(e)  # type: ignore[no-any-return]
           ^^^^^^^^^^^^^^^^^^^^^^^^^^^^
TypeError: page_not_found() takes 0 positional arguments but 1 was given
2024-05-27 11:30:58,353 - ERROR - Exception on /graphql [OPTIONS]
Traceback (most recent call last):
  File "/home/dominic-source/Projects/venv/lib/python3.11/site-packages/flask/app.py", line 870, in full_dispatch_request
    rv = self.dispatch_request()
         ^^^^^^^^^^^^^^^^^^^^^^^
  File "/home/dominic-source/Projects/venv/lib/python3.11/site-packages/flask/app.py", line 844, in dispatch_request
    self.raise_routing_exception(req)
  File "/home/dominic-source/Projects/venv/lib/python3.11/site-packages/flask/app.py", line 453, in raise_routing_exception
    raise request.routing_exception  # type: ignore[misc]
    ^^^^^^^^^^^^^^^^^^^^^^^^^^^^^^^
  File "/home/dominic-source/Projects/venv/lib/python3.11/site-packages/flask/ctx.py", line 362, in match_request
    result = self.url_adapter.match(return_rule=True)  # type: ignore
             ^^^^^^^^^^^^^^^^^^^^^^^^^^^^^^^^^^^^^^^^
  File "/home/dominic-source/Projects/venv/lib/python3.11/site-packages/werkzeug/routing/map.py", line 624, in match
    raise NotFound() from None
werkzeug.exceptions.NotFound: 404 Not Found: The requested URL was not found on the server. If you entered the URL manually please check your spelling and try again.

During handling of the above exception, another exception occurred:

Traceback (most recent call last):
  File "/home/dominic-source/Projects/venv/lib/python3.11/site-packages/flask/app.py", line 1463, in wsgi_app
    response = self.full_dispatch_request()
               ^^^^^^^^^^^^^^^^^^^^^^^^^^^^
  File "/home/dominic-source/Projects/venv/lib/python3.11/site-packages/flask/app.py", line 872, in full_dispatch_request
    rv = self.handle_user_exception(e)
         ^^^^^^^^^^^^^^^^^^^^^^^^^^^^^
  File "/home/dominic-source/Projects/venv/lib/python3.11/site-packages/flask/app.py", line 755, in handle_user_exception
    return self.handle_http_exception(e)
           ^^^^^^^^^^^^^^^^^^^^^^^^^^^^^
  File "/home/dominic-source/Projects/venv/lib/python3.11/site-packages/flask/app.py", line 730, in handle_http_exception
    return self.ensure_sync(handler)(e)  # type: ignore[no-any-return]
           ^^^^^^^^^^^^^^^^^^^^^^^^^^^^
TypeError: page_not_found() takes 0 positional arguments but 1 was given
2024-05-27 11:30:59,351 - ERROR - Exception on /graphql [OPTIONS]
Traceback (most recent call last):
  File "/home/dominic-source/Projects/venv/lib/python3.11/site-packages/flask/app.py", line 870, in full_dispatch_request
    rv = self.dispatch_request()
         ^^^^^^^^^^^^^^^^^^^^^^^
  File "/home/dominic-source/Projects/venv/lib/python3.11/site-packages/flask/app.py", line 844, in dispatch_request
    self.raise_routing_exception(req)
  File "/home/dominic-source/Projects/venv/lib/python3.11/site-packages/flask/app.py", line 453, in raise_routing_exception
    raise request.routing_exception  # type: ignore[misc]
    ^^^^^^^^^^^^^^^^^^^^^^^^^^^^^^^
  File "/home/dominic-source/Projects/venv/lib/python3.11/site-packages/flask/ctx.py", line 362, in match_request
    result = self.url_adapter.match(return_rule=True)  # type: ignore
             ^^^^^^^^^^^^^^^^^^^^^^^^^^^^^^^^^^^^^^^^
  File "/home/dominic-source/Projects/venv/lib/python3.11/site-packages/werkzeug/routing/map.py", line 624, in match
    raise NotFound() from None
werkzeug.exceptions.NotFound: 404 Not Found: The requested URL was not found on the server. If you entered the URL manually please check your spelling and try again.

During handling of the above exception, another exception occurred:

Traceback (most recent call last):
  File "/home/dominic-source/Projects/venv/lib/python3.11/site-packages/flask/app.py", line 1463, in wsgi_app
    response = self.full_dispatch_request()
               ^^^^^^^^^^^^^^^^^^^^^^^^^^^^
  File "/home/dominic-source/Projects/venv/lib/python3.11/site-packages/flask/app.py", line 872, in full_dispatch_request
    rv = self.handle_user_exception(e)
         ^^^^^^^^^^^^^^^^^^^^^^^^^^^^^
  File "/home/dominic-source/Projects/venv/lib/python3.11/site-packages/flask/app.py", line 755, in handle_user_exception
    return self.handle_http_exception(e)
           ^^^^^^^^^^^^^^^^^^^^^^^^^^^^^
  File "/home/dominic-source/Projects/venv/lib/python3.11/site-packages/flask/app.py", line 730, in handle_http_exception
    return self.ensure_sync(handler)(e)  # type: ignore[no-any-return]
           ^^^^^^^^^^^^^^^^^^^^^^^^^^^^
TypeError: page_not_found() takes 0 positional arguments but 1 was given
2024-05-27 11:31:00,352 - ERROR - Exception on /graphql [OPTIONS]
Traceback (most recent call last):
  File "/home/dominic-source/Projects/venv/lib/python3.11/site-packages/flask/app.py", line 870, in full_dispatch_request
    rv = self.dispatch_request()
         ^^^^^^^^^^^^^^^^^^^^^^^
  File "/home/dominic-source/Projects/venv/lib/python3.11/site-packages/flask/app.py", line 844, in dispatch_request
    self.raise_routing_exception(req)
  File "/home/dominic-source/Projects/venv/lib/python3.11/site-packages/flask/app.py", line 453, in raise_routing_exception
    raise request.routing_exception  # type: ignore[misc]
    ^^^^^^^^^^^^^^^^^^^^^^^^^^^^^^^
  File "/home/dominic-source/Projects/venv/lib/python3.11/site-packages/flask/ctx.py", line 362, in match_request
    result = self.url_adapter.match(return_rule=True)  # type: ignore
             ^^^^^^^^^^^^^^^^^^^^^^^^^^^^^^^^^^^^^^^^
  File "/home/dominic-source/Projects/venv/lib/python3.11/site-packages/werkzeug/routing/map.py", line 624, in match
    raise NotFound() from None
werkzeug.exceptions.NotFound: 404 Not Found: The requested URL was not found on the server. If you entered the URL manually please check your spelling and try again.

During handling of the above exception, another exception occurred:

Traceback (most recent call last):
  File "/home/dominic-source/Projects/venv/lib/python3.11/site-packages/flask/app.py", line 1463, in wsgi_app
    response = self.full_dispatch_request()
               ^^^^^^^^^^^^^^^^^^^^^^^^^^^^
  File "/home/dominic-source/Projects/venv/lib/python3.11/site-packages/flask/app.py", line 872, in full_dispatch_request
    rv = self.handle_user_exception(e)
         ^^^^^^^^^^^^^^^^^^^^^^^^^^^^^
  File "/home/dominic-source/Projects/venv/lib/python3.11/site-packages/flask/app.py", line 755, in handle_user_exception
    return self.handle_http_exception(e)
           ^^^^^^^^^^^^^^^^^^^^^^^^^^^^^
  File "/home/dominic-source/Projects/venv/lib/python3.11/site-packages/flask/app.py", line 730, in handle_http_exception
    return self.ensure_sync(handler)(e)  # type: ignore[no-any-return]
           ^^^^^^^^^^^^^^^^^^^^^^^^^^^^
TypeError: page_not_found() takes 0 positional arguments but 1 was given
2024-05-27 11:31:01,347 - ERROR - Exception on /graphql [OPTIONS]
Traceback (most recent call last):
  File "/home/dominic-source/Projects/venv/lib/python3.11/site-packages/flask/app.py", line 870, in full_dispatch_request
    rv = self.dispatch_request()
         ^^^^^^^^^^^^^^^^^^^^^^^
  File "/home/dominic-source/Projects/venv/lib/python3.11/site-packages/flask/app.py", line 844, in dispatch_request
    self.raise_routing_exception(req)
  File "/home/dominic-source/Projects/venv/lib/python3.11/site-packages/flask/app.py", line 453, in raise_routing_exception
    raise request.routing_exception  # type: ignore[misc]
    ^^^^^^^^^^^^^^^^^^^^^^^^^^^^^^^
  File "/home/dominic-source/Projects/venv/lib/python3.11/site-packages/flask/ctx.py", line 362, in match_request
    result = self.url_adapter.match(return_rule=True)  # type: ignore
             ^^^^^^^^^^^^^^^^^^^^^^^^^^^^^^^^^^^^^^^^
  File "/home/dominic-source/Projects/venv/lib/python3.11/site-packages/werkzeug/routing/map.py", line 624, in match
    raise NotFound() from None
werkzeug.exceptions.NotFound: 404 Not Found: The requested URL was not found on the server. If you entered the URL manually please check your spelling and try again.

During handling of the above exception, another exception occurred:

Traceback (most recent call last):
  File "/home/dominic-source/Projects/venv/lib/python3.11/site-packages/flask/app.py", line 1463, in wsgi_app
    response = self.full_dispatch_request()
               ^^^^^^^^^^^^^^^^^^^^^^^^^^^^
  File "/home/dominic-source/Projects/venv/lib/python3.11/site-packages/flask/app.py", line 872, in full_dispatch_request
    rv = self.handle_user_exception(e)
         ^^^^^^^^^^^^^^^^^^^^^^^^^^^^^
  File "/home/dominic-source/Projects/venv/lib/python3.11/site-packages/flask/app.py", line 755, in handle_user_exception
    return self.handle_http_exception(e)
           ^^^^^^^^^^^^^^^^^^^^^^^^^^^^^
  File "/home/dominic-source/Projects/venv/lib/python3.11/site-packages/flask/app.py", line 730, in handle_http_exception
    return self.ensure_sync(handler)(e)  # type: ignore[no-any-return]
           ^^^^^^^^^^^^^^^^^^^^^^^^^^^^
TypeError: page_not_found() takes 0 positional arguments but 1 was given
2024-05-27 11:31:02,353 - ERROR - Exception on /graphql [OPTIONS]
Traceback (most recent call last):
  File "/home/dominic-source/Projects/venv/lib/python3.11/site-packages/flask/app.py", line 870, in full_dispatch_request
    rv = self.dispatch_request()
         ^^^^^^^^^^^^^^^^^^^^^^^
  File "/home/dominic-source/Projects/venv/lib/python3.11/site-packages/flask/app.py", line 844, in dispatch_request
    self.raise_routing_exception(req)
  File "/home/dominic-source/Projects/venv/lib/python3.11/site-packages/flask/app.py", line 453, in raise_routing_exception
    raise request.routing_exception  # type: ignore[misc]
    ^^^^^^^^^^^^^^^^^^^^^^^^^^^^^^^
  File "/home/dominic-source/Projects/venv/lib/python3.11/site-packages/flask/ctx.py", line 362, in match_request
    result = self.url_adapter.match(return_rule=True)  # type: ignore
             ^^^^^^^^^^^^^^^^^^^^^^^^^^^^^^^^^^^^^^^^
  File "/home/dominic-source/Projects/venv/lib/python3.11/site-packages/werkzeug/routing/map.py", line 624, in match
    raise NotFound() from None
werkzeug.exceptions.NotFound: 404 Not Found: The requested URL was not found on the server. If you entered the URL manually please check your spelling and try again.

During handling of the above exception, another exception occurred:

Traceback (most recent call last):
  File "/home/dominic-source/Projects/venv/lib/python3.11/site-packages/flask/app.py", line 1463, in wsgi_app
    response = self.full_dispatch_request()
               ^^^^^^^^^^^^^^^^^^^^^^^^^^^^
  File "/home/dominic-source/Projects/venv/lib/python3.11/site-packages/flask/app.py", line 872, in full_dispatch_request
    rv = self.handle_user_exception(e)
         ^^^^^^^^^^^^^^^^^^^^^^^^^^^^^
  File "/home/dominic-source/Projects/venv/lib/python3.11/site-packages/flask/app.py", line 755, in handle_user_exception
    return self.handle_http_exception(e)
           ^^^^^^^^^^^^^^^^^^^^^^^^^^^^^
  File "/home/dominic-source/Projects/venv/lib/python3.11/site-packages/flask/app.py", line 730, in handle_http_exception
    return self.ensure_sync(handler)(e)  # type: ignore[no-any-return]
           ^^^^^^^^^^^^^^^^^^^^^^^^^^^^
TypeError: page_not_found() takes 0 positional arguments but 1 was given
2024-05-27 11:31:03,354 - ERROR - Exception on /graphql [OPTIONS]
Traceback (most recent call last):
  File "/home/dominic-source/Projects/venv/lib/python3.11/site-packages/flask/app.py", line 870, in full_dispatch_request
    rv = self.dispatch_request()
         ^^^^^^^^^^^^^^^^^^^^^^^
  File "/home/dominic-source/Projects/venv/lib/python3.11/site-packages/flask/app.py", line 844, in dispatch_request
    self.raise_routing_exception(req)
  File "/home/dominic-source/Projects/venv/lib/python3.11/site-packages/flask/app.py", line 453, in raise_routing_exception
    raise request.routing_exception  # type: ignore[misc]
    ^^^^^^^^^^^^^^^^^^^^^^^^^^^^^^^
  File "/home/dominic-source/Projects/venv/lib/python3.11/site-packages/flask/ctx.py", line 362, in match_request
    result = self.url_adapter.match(return_rule=True)  # type: ignore
             ^^^^^^^^^^^^^^^^^^^^^^^^^^^^^^^^^^^^^^^^
  File "/home/dominic-source/Projects/venv/lib/python3.11/site-packages/werkzeug/routing/map.py", line 624, in match
    raise NotFound() from None
werkzeug.exceptions.NotFound: 404 Not Found: The requested URL was not found on the server. If you entered the URL manually please check your spelling and try again.

During handling of the above exception, another exception occurred:

Traceback (most recent call last):
  File "/home/dominic-source/Projects/venv/lib/python3.11/site-packages/flask/app.py", line 1463, in wsgi_app
    response = self.full_dispatch_request()
               ^^^^^^^^^^^^^^^^^^^^^^^^^^^^
  File "/home/dominic-source/Projects/venv/lib/python3.11/site-packages/flask/app.py", line 872, in full_dispatch_request
    rv = self.handle_user_exception(e)
         ^^^^^^^^^^^^^^^^^^^^^^^^^^^^^
  File "/home/dominic-source/Projects/venv/lib/python3.11/site-packages/flask/app.py", line 755, in handle_user_exception
    return self.handle_http_exception(e)
           ^^^^^^^^^^^^^^^^^^^^^^^^^^^^^
  File "/home/dominic-source/Projects/venv/lib/python3.11/site-packages/flask/app.py", line 730, in handle_http_exception
    return self.ensure_sync(handler)(e)  # type: ignore[no-any-return]
           ^^^^^^^^^^^^^^^^^^^^^^^^^^^^
TypeError: page_not_found() takes 0 positional arguments but 1 was given
2024-05-27 11:31:04,353 - ERROR - Exception on /graphql [OPTIONS]
Traceback (most recent call last):
  File "/home/dominic-source/Projects/venv/lib/python3.11/site-packages/flask/app.py", line 870, in full_dispatch_request
    rv = self.dispatch_request()
         ^^^^^^^^^^^^^^^^^^^^^^^
  File "/home/dominic-source/Projects/venv/lib/python3.11/site-packages/flask/app.py", line 844, in dispatch_request
    self.raise_routing_exception(req)
  File "/home/dominic-source/Projects/venv/lib/python3.11/site-packages/flask/app.py", line 453, in raise_routing_exception
    raise request.routing_exception  # type: ignore[misc]
    ^^^^^^^^^^^^^^^^^^^^^^^^^^^^^^^
  File "/home/dominic-source/Projects/venv/lib/python3.11/site-packages/flask/ctx.py", line 362, in match_request
    result = self.url_adapter.match(return_rule=True)  # type: ignore
             ^^^^^^^^^^^^^^^^^^^^^^^^^^^^^^^^^^^^^^^^
  File "/home/dominic-source/Projects/venv/lib/python3.11/site-packages/werkzeug/routing/map.py", line 624, in match
    raise NotFound() from None
werkzeug.exceptions.NotFound: 404 Not Found: The requested URL was not found on the server. If you entered the URL manually please check your spelling and try again.

During handling of the above exception, another exception occurred:

Traceback (most recent call last):
  File "/home/dominic-source/Projects/venv/lib/python3.11/site-packages/flask/app.py", line 1463, in wsgi_app
    response = self.full_dispatch_request()
               ^^^^^^^^^^^^^^^^^^^^^^^^^^^^
  File "/home/dominic-source/Projects/venv/lib/python3.11/site-packages/flask/app.py", line 872, in full_dispatch_request
    rv = self.handle_user_exception(e)
         ^^^^^^^^^^^^^^^^^^^^^^^^^^^^^
  File "/home/dominic-source/Projects/venv/lib/python3.11/site-packages/flask/app.py", line 755, in handle_user_exception
    return self.handle_http_exception(e)
           ^^^^^^^^^^^^^^^^^^^^^^^^^^^^^
  File "/home/dominic-source/Projects/venv/lib/python3.11/site-packages/flask/app.py", line 730, in handle_http_exception
    return self.ensure_sync(handler)(e)  # type: ignore[no-any-return]
           ^^^^^^^^^^^^^^^^^^^^^^^^^^^^
TypeError: page_not_found() takes 0 positional arguments but 1 was given
2024-05-27 11:31:05,352 - ERROR - Exception on /graphql [OPTIONS]
Traceback (most recent call last):
  File "/home/dominic-source/Projects/venv/lib/python3.11/site-packages/flask/app.py", line 870, in full_dispatch_request
    rv = self.dispatch_request()
         ^^^^^^^^^^^^^^^^^^^^^^^
  File "/home/dominic-source/Projects/venv/lib/python3.11/site-packages/flask/app.py", line 844, in dispatch_request
    self.raise_routing_exception(req)
  File "/home/dominic-source/Projects/venv/lib/python3.11/site-packages/flask/app.py", line 453, in raise_routing_exception
    raise request.routing_exception  # type: ignore[misc]
    ^^^^^^^^^^^^^^^^^^^^^^^^^^^^^^^
  File "/home/dominic-source/Projects/venv/lib/python3.11/site-packages/flask/ctx.py", line 362, in match_request
    result = self.url_adapter.match(return_rule=True)  # type: ignore
             ^^^^^^^^^^^^^^^^^^^^^^^^^^^^^^^^^^^^^^^^
  File "/home/dominic-source/Projects/venv/lib/python3.11/site-packages/werkzeug/routing/map.py", line 624, in match
    raise NotFound() from None
werkzeug.exceptions.NotFound: 404 Not Found: The requested URL was not found on the server. If you entered the URL manually please check your spelling and try again.

During handling of the above exception, another exception occurred:

Traceback (most recent call last):
  File "/home/dominic-source/Projects/venv/lib/python3.11/site-packages/flask/app.py", line 1463, in wsgi_app
    response = self.full_dispatch_request()
               ^^^^^^^^^^^^^^^^^^^^^^^^^^^^
  File "/home/dominic-source/Projects/venv/lib/python3.11/site-packages/flask/app.py", line 872, in full_dispatch_request
    rv = self.handle_user_exception(e)
         ^^^^^^^^^^^^^^^^^^^^^^^^^^^^^
  File "/home/dominic-source/Projects/venv/lib/python3.11/site-packages/flask/app.py", line 755, in handle_user_exception
    return self.handle_http_exception(e)
           ^^^^^^^^^^^^^^^^^^^^^^^^^^^^^
  File "/home/dominic-source/Projects/venv/lib/python3.11/site-packages/flask/app.py", line 730, in handle_http_exception
    return self.ensure_sync(handler)(e)  # type: ignore[no-any-return]
           ^^^^^^^^^^^^^^^^^^^^^^^^^^^^
TypeError: page_not_found() takes 0 positional arguments but 1 was given
2024-05-27 11:31:06,350 - ERROR - Exception on /graphql [OPTIONS]
Traceback (most recent call last):
  File "/home/dominic-source/Projects/venv/lib/python3.11/site-packages/flask/app.py", line 870, in full_dispatch_request
    rv = self.dispatch_request()
         ^^^^^^^^^^^^^^^^^^^^^^^
  File "/home/dominic-source/Projects/venv/lib/python3.11/site-packages/flask/app.py", line 844, in dispatch_request
    self.raise_routing_exception(req)
  File "/home/dominic-source/Projects/venv/lib/python3.11/site-packages/flask/app.py", line 453, in raise_routing_exception
    raise request.routing_exception  # type: ignore[misc]
    ^^^^^^^^^^^^^^^^^^^^^^^^^^^^^^^
  File "/home/dominic-source/Projects/venv/lib/python3.11/site-packages/flask/ctx.py", line 362, in match_request
    result = self.url_adapter.match(return_rule=True)  # type: ignore
             ^^^^^^^^^^^^^^^^^^^^^^^^^^^^^^^^^^^^^^^^
  File "/home/dominic-source/Projects/venv/lib/python3.11/site-packages/werkzeug/routing/map.py", line 624, in match
    raise NotFound() from None
werkzeug.exceptions.NotFound: 404 Not Found: The requested URL was not found on the server. If you entered the URL manually please check your spelling and try again.

During handling of the above exception, another exception occurred:

Traceback (most recent call last):
  File "/home/dominic-source/Projects/venv/lib/python3.11/site-packages/flask/app.py", line 1463, in wsgi_app
    response = self.full_dispatch_request()
               ^^^^^^^^^^^^^^^^^^^^^^^^^^^^
  File "/home/dominic-source/Projects/venv/lib/python3.11/site-packages/flask/app.py", line 872, in full_dispatch_request
    rv = self.handle_user_exception(e)
         ^^^^^^^^^^^^^^^^^^^^^^^^^^^^^
  File "/home/dominic-source/Projects/venv/lib/python3.11/site-packages/flask/app.py", line 755, in handle_user_exception
    return self.handle_http_exception(e)
           ^^^^^^^^^^^^^^^^^^^^^^^^^^^^^
  File "/home/dominic-source/Projects/venv/lib/python3.11/site-packages/flask/app.py", line 730, in handle_http_exception
    return self.ensure_sync(handler)(e)  # type: ignore[no-any-return]
           ^^^^^^^^^^^^^^^^^^^^^^^^^^^^
TypeError: page_not_found() takes 0 positional arguments but 1 was given
2024-05-27 11:31:07,347 - ERROR - Exception on /graphql [OPTIONS]
Traceback (most recent call last):
  File "/home/dominic-source/Projects/venv/lib/python3.11/site-packages/flask/app.py", line 870, in full_dispatch_request
    rv = self.dispatch_request()
         ^^^^^^^^^^^^^^^^^^^^^^^
  File "/home/dominic-source/Projects/venv/lib/python3.11/site-packages/flask/app.py", line 844, in dispatch_request
    self.raise_routing_exception(req)
  File "/home/dominic-source/Projects/venv/lib/python3.11/site-packages/flask/app.py", line 453, in raise_routing_exception
    raise request.routing_exception  # type: ignore[misc]
    ^^^^^^^^^^^^^^^^^^^^^^^^^^^^^^^
  File "/home/dominic-source/Projects/venv/lib/python3.11/site-packages/flask/ctx.py", line 362, in match_request
    result = self.url_adapter.match(return_rule=True)  # type: ignore
             ^^^^^^^^^^^^^^^^^^^^^^^^^^^^^^^^^^^^^^^^
  File "/home/dominic-source/Projects/venv/lib/python3.11/site-packages/werkzeug/routing/map.py", line 624, in match
    raise NotFound() from None
werkzeug.exceptions.NotFound: 404 Not Found: The requested URL was not found on the server. If you entered the URL manually please check your spelling and try again.

During handling of the above exception, another exception occurred:

Traceback (most recent call last):
  File "/home/dominic-source/Projects/venv/lib/python3.11/site-packages/flask/app.py", line 1463, in wsgi_app
    response = self.full_dispatch_request()
               ^^^^^^^^^^^^^^^^^^^^^^^^^^^^
  File "/home/dominic-source/Projects/venv/lib/python3.11/site-packages/flask/app.py", line 872, in full_dispatch_request
    rv = self.handle_user_exception(e)
         ^^^^^^^^^^^^^^^^^^^^^^^^^^^^^
  File "/home/dominic-source/Projects/venv/lib/python3.11/site-packages/flask/app.py", line 755, in handle_user_exception
    return self.handle_http_exception(e)
           ^^^^^^^^^^^^^^^^^^^^^^^^^^^^^
  File "/home/dominic-source/Projects/venv/lib/python3.11/site-packages/flask/app.py", line 730, in handle_http_exception
    return self.ensure_sync(handler)(e)  # type: ignore[no-any-return]
           ^^^^^^^^^^^^^^^^^^^^^^^^^^^^
TypeError: page_not_found() takes 0 positional arguments but 1 was given
2024-05-27 11:31:08,353 - ERROR - Exception on /graphql [OPTIONS]
Traceback (most recent call last):
  File "/home/dominic-source/Projects/venv/lib/python3.11/site-packages/flask/app.py", line 870, in full_dispatch_request
    rv = self.dispatch_request()
         ^^^^^^^^^^^^^^^^^^^^^^^
  File "/home/dominic-source/Projects/venv/lib/python3.11/site-packages/flask/app.py", line 844, in dispatch_request
    self.raise_routing_exception(req)
  File "/home/dominic-source/Projects/venv/lib/python3.11/site-packages/flask/app.py", line 453, in raise_routing_exception
    raise request.routing_exception  # type: ignore[misc]
    ^^^^^^^^^^^^^^^^^^^^^^^^^^^^^^^
  File "/home/dominic-source/Projects/venv/lib/python3.11/site-packages/flask/ctx.py", line 362, in match_request
    result = self.url_adapter.match(return_rule=True)  # type: ignore
             ^^^^^^^^^^^^^^^^^^^^^^^^^^^^^^^^^^^^^^^^
  File "/home/dominic-source/Projects/venv/lib/python3.11/site-packages/werkzeug/routing/map.py", line 624, in match
    raise NotFound() from None
werkzeug.exceptions.NotFound: 404 Not Found: The requested URL was not found on the server. If you entered the URL manually please check your spelling and try again.

During handling of the above exception, another exception occurred:

Traceback (most recent call last):
  File "/home/dominic-source/Projects/venv/lib/python3.11/site-packages/flask/app.py", line 1463, in wsgi_app
    response = self.full_dispatch_request()
               ^^^^^^^^^^^^^^^^^^^^^^^^^^^^
  File "/home/dominic-source/Projects/venv/lib/python3.11/site-packages/flask/app.py", line 872, in full_dispatch_request
    rv = self.handle_user_exception(e)
         ^^^^^^^^^^^^^^^^^^^^^^^^^^^^^
  File "/home/dominic-source/Projects/venv/lib/python3.11/site-packages/flask/app.py", line 755, in handle_user_exception
    return self.handle_http_exception(e)
           ^^^^^^^^^^^^^^^^^^^^^^^^^^^^^
  File "/home/dominic-source/Projects/venv/lib/python3.11/site-packages/flask/app.py", line 730, in handle_http_exception
    return self.ensure_sync(handler)(e)  # type: ignore[no-any-return]
           ^^^^^^^^^^^^^^^^^^^^^^^^^^^^
TypeError: page_not_found() takes 0 positional arguments but 1 was given
2024-05-27 11:31:09,351 - ERROR - Exception on /graphql [OPTIONS]
Traceback (most recent call last):
  File "/home/dominic-source/Projects/venv/lib/python3.11/site-packages/flask/app.py", line 870, in full_dispatch_request
    rv = self.dispatch_request()
         ^^^^^^^^^^^^^^^^^^^^^^^
  File "/home/dominic-source/Projects/venv/lib/python3.11/site-packages/flask/app.py", line 844, in dispatch_request
    self.raise_routing_exception(req)
  File "/home/dominic-source/Projects/venv/lib/python3.11/site-packages/flask/app.py", line 453, in raise_routing_exception
    raise request.routing_exception  # type: ignore[misc]
    ^^^^^^^^^^^^^^^^^^^^^^^^^^^^^^^
  File "/home/dominic-source/Projects/venv/lib/python3.11/site-packages/flask/ctx.py", line 362, in match_request
    result = self.url_adapter.match(return_rule=True)  # type: ignore
             ^^^^^^^^^^^^^^^^^^^^^^^^^^^^^^^^^^^^^^^^
  File "/home/dominic-source/Projects/venv/lib/python3.11/site-packages/werkzeug/routing/map.py", line 624, in match
    raise NotFound() from None
werkzeug.exceptions.NotFound: 404 Not Found: The requested URL was not found on the server. If you entered the URL manually please check your spelling and try again.

During handling of the above exception, another exception occurred:

Traceback (most recent call last):
  File "/home/dominic-source/Projects/venv/lib/python3.11/site-packages/flask/app.py", line 1463, in wsgi_app
    response = self.full_dispatch_request()
               ^^^^^^^^^^^^^^^^^^^^^^^^^^^^
  File "/home/dominic-source/Projects/venv/lib/python3.11/site-packages/flask/app.py", line 872, in full_dispatch_request
    rv = self.handle_user_exception(e)
         ^^^^^^^^^^^^^^^^^^^^^^^^^^^^^
  File "/home/dominic-source/Projects/venv/lib/python3.11/site-packages/flask/app.py", line 755, in handle_user_exception
    return self.handle_http_exception(e)
           ^^^^^^^^^^^^^^^^^^^^^^^^^^^^^
  File "/home/dominic-source/Projects/venv/lib/python3.11/site-packages/flask/app.py", line 730, in handle_http_exception
    return self.ensure_sync(handler)(e)  # type: ignore[no-any-return]
           ^^^^^^^^^^^^^^^^^^^^^^^^^^^^
TypeError: page_not_found() takes 0 positional arguments but 1 was given
2024-05-27 11:31:10,351 - ERROR - Exception on /graphql [OPTIONS]
Traceback (most recent call last):
  File "/home/dominic-source/Projects/venv/lib/python3.11/site-packages/flask/app.py", line 870, in full_dispatch_request
    rv = self.dispatch_request()
         ^^^^^^^^^^^^^^^^^^^^^^^
  File "/home/dominic-source/Projects/venv/lib/python3.11/site-packages/flask/app.py", line 844, in dispatch_request
    self.raise_routing_exception(req)
  File "/home/dominic-source/Projects/venv/lib/python3.11/site-packages/flask/app.py", line 453, in raise_routing_exception
    raise request.routing_exception  # type: ignore[misc]
    ^^^^^^^^^^^^^^^^^^^^^^^^^^^^^^^
  File "/home/dominic-source/Projects/venv/lib/python3.11/site-packages/flask/ctx.py", line 362, in match_request
    result = self.url_adapter.match(return_rule=True)  # type: ignore
             ^^^^^^^^^^^^^^^^^^^^^^^^^^^^^^^^^^^^^^^^
  File "/home/dominic-source/Projects/venv/lib/python3.11/site-packages/werkzeug/routing/map.py", line 624, in match
    raise NotFound() from None
werkzeug.exceptions.NotFound: 404 Not Found: The requested URL was not found on the server. If you entered the URL manually please check your spelling and try again.

During handling of the above exception, another exception occurred:

Traceback (most recent call last):
  File "/home/dominic-source/Projects/venv/lib/python3.11/site-packages/flask/app.py", line 1463, in wsgi_app
    response = self.full_dispatch_request()
               ^^^^^^^^^^^^^^^^^^^^^^^^^^^^
  File "/home/dominic-source/Projects/venv/lib/python3.11/site-packages/flask/app.py", line 872, in full_dispatch_request
    rv = self.handle_user_exception(e)
         ^^^^^^^^^^^^^^^^^^^^^^^^^^^^^
  File "/home/dominic-source/Projects/venv/lib/python3.11/site-packages/flask/app.py", line 755, in handle_user_exception
    return self.handle_http_exception(e)
           ^^^^^^^^^^^^^^^^^^^^^^^^^^^^^
  File "/home/dominic-source/Projects/venv/lib/python3.11/site-packages/flask/app.py", line 730, in handle_http_exception
    return self.ensure_sync(handler)(e)  # type: ignore[no-any-return]
           ^^^^^^^^^^^^^^^^^^^^^^^^^^^^
TypeError: page_not_found() takes 0 positional arguments but 1 was given
2024-05-27 11:31:11,350 - ERROR - Exception on /graphql [OPTIONS]
Traceback (most recent call last):
  File "/home/dominic-source/Projects/venv/lib/python3.11/site-packages/flask/app.py", line 870, in full_dispatch_request
    rv = self.dispatch_request()
         ^^^^^^^^^^^^^^^^^^^^^^^
  File "/home/dominic-source/Projects/venv/lib/python3.11/site-packages/flask/app.py", line 844, in dispatch_request
    self.raise_routing_exception(req)
  File "/home/dominic-source/Projects/venv/lib/python3.11/site-packages/flask/app.py", line 453, in raise_routing_exception
    raise request.routing_exception  # type: ignore[misc]
    ^^^^^^^^^^^^^^^^^^^^^^^^^^^^^^^
  File "/home/dominic-source/Projects/venv/lib/python3.11/site-packages/flask/ctx.py", line 362, in match_request
    result = self.url_adapter.match(return_rule=True)  # type: ignore
             ^^^^^^^^^^^^^^^^^^^^^^^^^^^^^^^^^^^^^^^^
  File "/home/dominic-source/Projects/venv/lib/python3.11/site-packages/werkzeug/routing/map.py", line 624, in match
    raise NotFound() from None
werkzeug.exceptions.NotFound: 404 Not Found: The requested URL was not found on the server. If you entered the URL manually please check your spelling and try again.

During handling of the above exception, another exception occurred:

Traceback (most recent call last):
  File "/home/dominic-source/Projects/venv/lib/python3.11/site-packages/flask/app.py", line 1463, in wsgi_app
    response = self.full_dispatch_request()
               ^^^^^^^^^^^^^^^^^^^^^^^^^^^^
  File "/home/dominic-source/Projects/venv/lib/python3.11/site-packages/flask/app.py", line 872, in full_dispatch_request
    rv = self.handle_user_exception(e)
         ^^^^^^^^^^^^^^^^^^^^^^^^^^^^^
  File "/home/dominic-source/Projects/venv/lib/python3.11/site-packages/flask/app.py", line 755, in handle_user_exception
    return self.handle_http_exception(e)
           ^^^^^^^^^^^^^^^^^^^^^^^^^^^^^
  File "/home/dominic-source/Projects/venv/lib/python3.11/site-packages/flask/app.py", line 730, in handle_http_exception
    return self.ensure_sync(handler)(e)  # type: ignore[no-any-return]
           ^^^^^^^^^^^^^^^^^^^^^^^^^^^^
TypeError: page_not_found() takes 0 positional arguments but 1 was given
2024-05-27 11:31:12,352 - ERROR - Exception on /graphql [OPTIONS]
Traceback (most recent call last):
  File "/home/dominic-source/Projects/venv/lib/python3.11/site-packages/flask/app.py", line 870, in full_dispatch_request
    rv = self.dispatch_request()
         ^^^^^^^^^^^^^^^^^^^^^^^
  File "/home/dominic-source/Projects/venv/lib/python3.11/site-packages/flask/app.py", line 844, in dispatch_request
    self.raise_routing_exception(req)
  File "/home/dominic-source/Projects/venv/lib/python3.11/site-packages/flask/app.py", line 453, in raise_routing_exception
    raise request.routing_exception  # type: ignore[misc]
    ^^^^^^^^^^^^^^^^^^^^^^^^^^^^^^^
  File "/home/dominic-source/Projects/venv/lib/python3.11/site-packages/flask/ctx.py", line 362, in match_request
    result = self.url_adapter.match(return_rule=True)  # type: ignore
             ^^^^^^^^^^^^^^^^^^^^^^^^^^^^^^^^^^^^^^^^
  File "/home/dominic-source/Projects/venv/lib/python3.11/site-packages/werkzeug/routing/map.py", line 624, in match
    raise NotFound() from None
werkzeug.exceptions.NotFound: 404 Not Found: The requested URL was not found on the server. If you entered the URL manually please check your spelling and try again.

During handling of the above exception, another exception occurred:

Traceback (most recent call last):
  File "/home/dominic-source/Projects/venv/lib/python3.11/site-packages/flask/app.py", line 1463, in wsgi_app
    response = self.full_dispatch_request()
               ^^^^^^^^^^^^^^^^^^^^^^^^^^^^
  File "/home/dominic-source/Projects/venv/lib/python3.11/site-packages/flask/app.py", line 872, in full_dispatch_request
    rv = self.handle_user_exception(e)
         ^^^^^^^^^^^^^^^^^^^^^^^^^^^^^
  File "/home/dominic-source/Projects/venv/lib/python3.11/site-packages/flask/app.py", line 755, in handle_user_exception
    return self.handle_http_exception(e)
           ^^^^^^^^^^^^^^^^^^^^^^^^^^^^^
  File "/home/dominic-source/Projects/venv/lib/python3.11/site-packages/flask/app.py", line 730, in handle_http_exception
    return self.ensure_sync(handler)(e)  # type: ignore[no-any-return]
           ^^^^^^^^^^^^^^^^^^^^^^^^^^^^
TypeError: page_not_found() takes 0 positional arguments but 1 was given
2024-05-27 12:00:05,083 - ERROR - Error occured:
Traceback (most recent call last):
  File "/home/dominic-source/Projects/Home_Deliverer/flask_server/views/v1/payment.py", line 20, in update_payment
    payment = Payment.query.filter_by(id=id).one()
              ^^^^^^^^^^^^^^^^^^^^^^^^^^^^^^^^^^^^
  File "/home/dominic-source/Projects/venv/lib/python3.11/site-packages/sqlalchemy/orm/query.py", line 2778, in one
    return self._iter().one()  # type: ignore
           ^^^^^^^^^^^^^^^^^^
  File "/home/dominic-source/Projects/venv/lib/python3.11/site-packages/sqlalchemy/engine/result.py", line 1810, in one
    return self._only_one_row(
           ^^^^^^^^^^^^^^^^^^^
  File "/home/dominic-source/Projects/venv/lib/python3.11/site-packages/sqlalchemy/engine/result.py", line 752, in _only_one_row
    raise exc.NoResultFound(
sqlalchemy.exc.NoResultFound: No row was found when one was required
2024-05-27 12:01:45,189 - ERROR - Error occured:
Traceback (most recent call last):
  File "/home/dominic-source/Projects/Home_Deliverer/flask_server/views/v1/payment.py", line 96, in get_my_payments
    transaction = [{
                  ^^
  File "/home/dominic-source/Projects/Home_Deliverer/flask_server/views/v1/payment.py", line 100, in <listcomp>
    'Payment_status': payment.payment_status,
                      ^^^^^^^^^^^^^^^^^^^^^^
AttributeError: 'Payment' object has no attribute 'payment_status'
2024-05-27 12:02:46,838 - ERROR - Error occured:
Traceback (most recent call last):
  File "/home/dominic-source/Projects/Home_Deliverer/flask_server/views/v1/payment.py", line 96, in get_my_payments
    transaction = [{
                  ^^
  File "/home/dominic-source/Projects/Home_Deliverer/flask_server/views/v1/payment.py", line 100, in <listcomp>
    'Payment_status': payment.payment_status,
                      ^^^^^^^^^^^^^^^^^^^^^^
AttributeError: 'Payment' object has no attribute 'payment_status'
2024-05-27 12:03:07,127 - ERROR - Error occured:
Traceback (most recent call last):
  File "/home/dominic-source/Projects/Home_Deliverer/flask_server/views/v1/payment.py", line 96, in get_my_payments
    transaction = [{
                  ^^
  File "/home/dominic-source/Projects/Home_Deliverer/flask_server/views/v1/payment.py", line 100, in <listcomp>
    'Payment_status': payment.payment_status,
                      ^^^^^^^^^^^^^^^^^^^^^^
AttributeError: 'Payment' object has no attribute 'payment_status'
2024-05-27 12:03:28,197 - ERROR - Error occured:
Traceback (most recent call last):
  File "/home/dominic-source/Projects/Home_Deliverer/flask_server/views/v1/payment.py", line 96, in get_my_payments
    transaction = [{
                  ^^
  File "/home/dominic-source/Projects/Home_Deliverer/flask_server/views/v1/payment.py", line 100, in <listcomp>
    'Payment_status': payment.payment_status,
                      ^^^^^^^^^^^^^^^^^^^^^^
AttributeError: 'Payment' object has no attribute 'payment_status'
2024-05-27 12:04:31,146 - ERROR - Error occured:
Traceback (most recent call last):
  File "/home/dominic-source/Projects/Home_Deliverer/flask_server/views/v1/payment.py", line 96, in get_my_payments
    transaction = [{
                  ^^
  File "/home/dominic-source/Projects/Home_Deliverer/flask_server/views/v1/payment.py", line 102, in <listcomp>
    'Amount': payment.total_amount if query.seller_id == user_id or
              ^^^^^^^^^^^^^^^^^^^^
AttributeError: 'Payment' object has no attribute 'total_amount'
