2024-05-06 11:19:03,886 - DEBUG - Using selector: EpollSelector
2024-05-06 11:19:03,886 - INFO - Loop 1
2024-05-06 11:19:42,477 - INFO - Received task from queue
2024-05-06 11:19:47,862 - INFO - Email task with user id = 4 is completed!
2024-05-06 11:19:47,863 - INFO - Loop 1
2024-05-06 11:20:44,945 - DEBUG - Using selector: EpollSelector
2024-05-06 11:20:44,945 - INFO - Loop 1
2024-05-06 11:20:54,313 - INFO - Received task from queue
2024-05-06 11:21:03,009 - INFO - Email task with user id = 4 is completed!
2024-05-06 11:21:03,010 - INFO - Loop 1
2024-05-10 12:13:10,290 - ERROR - Error occured:
Traceback (most recent call last):
  File "/home/dominic-source/Projects/Home_Deliverer/flask_server/views/v1/category.py", line 20, in create_category
    return jsonify({'success': category.category_name + ' ' + category.id}), 200
                               ~~~~~~~~~~~~~~~~~~~~~~~~~~~~~^~~~~~~~~~~~~
TypeError: can only concatenate str (not "int") to str
2024-05-10 12:15:13,300 - ERROR - Error occured:
Traceback (most recent call last):
  File "/home/dominic-source/Projects/Home_Deliverer/flask_server/views/v1/category.py", line 20, in create_category
    return jsonify({'success': category.category_name + ' ' + category.id}), 200
                               ~~~~~~~~~~~~~~~~~~~~~~~~~~~~~^~~~~~~~~~~~~
TypeError: can only concatenate str (not "int") to str
2024-05-10 12:21:03,932 - ERROR - Error occured:
Traceback (most recent call last):
  File "/home/dominic-source/Projects/Home_Deliverer/flask_server/views/v1/category.py", line 20, in create_category
    return jsonify({'success': category.category_name + ' ' + category.id}), 200
                               ~~~~~~~~~~~~~~~~~~~~~~~~~~~~~^~~~~~~~~~~~~
TypeError: can only concatenate str (not "int") to str
2024-05-10 15:40:00,902 - ERROR - Error occured:
Traceback (most recent call last):
  File "/home/dominic-source/Projects/Home_Deliverer/flask_server/views/v1/category.py", line 55, in get_category
    return jsonify(category), 200
           ^^^^^^^^^^^^^^^^^
  File "/home/dominic-source/Projects/venv/lib/python3.11/site-packages/flask/json/__init__.py", line 170, in jsonify
    return current_app.json.response(*args, **kwargs)  # type: ignore[return-value]
           ^^^^^^^^^^^^^^^^^^^^^^^^^^^^^^^^^^^^^^^^^^
  File "/home/dominic-source/Projects/venv/lib/python3.11/site-packages/flask/json/provider.py", line 214, in response
    f"{self.dumps(obj, **dump_args)}\n", mimetype=self.mimetype
       ^^^^^^^^^^^^^^^^^^^^^^^^^^^^
  File "/home/dominic-source/Projects/venv/lib/python3.11/site-packages/flask/json/provider.py", line 179, in dumps
    return json.dumps(obj, **kwargs)
           ^^^^^^^^^^^^^^^^^^^^^^^^^
  File "/usr/lib/python3.11/json/__init__.py", line 238, in dumps
    **kw).encode(obj)
          ^^^^^^^^^^^
  File "/usr/lib/python3.11/json/encoder.py", line 200, in encode
    chunks = self.iterencode(o, _one_shot=True)
             ^^^^^^^^^^^^^^^^^^^^^^^^^^^^^^^^^^
  File "/usr/lib/python3.11/json/encoder.py", line 258, in iterencode
    return _iterencode(o, 0)
           ^^^^^^^^^^^^^^^^^
  File "/home/dominic-source/Projects/venv/lib/python3.11/site-packages/flask/json/provider.py", line 121, in _default
    raise TypeError(f"Object of type {type(o).__name__} is not JSON serializable")
TypeError: Object of type Category is not JSON serializable
2024-05-10 15:41:07,504 - ERROR - Error occured:
Traceback (most recent call last):
  File "/home/dominic-source/Projects/Home_Deliverer/flask_server/views/v1/category.py", line 54, in get_category
    return jsonify(category), 200
           ^^^^^^^^^^^^^^^^^
  File "/home/dominic-source/Projects/venv/lib/python3.11/site-packages/flask/json/__init__.py", line 170, in jsonify
    return current_app.json.response(*args, **kwargs)  # type: ignore[return-value]
           ^^^^^^^^^^^^^^^^^^^^^^^^^^^^^^^^^^^^^^^^^^
  File "/home/dominic-source/Projects/venv/lib/python3.11/site-packages/flask/json/provider.py", line 214, in response
    f"{self.dumps(obj, **dump_args)}\n", mimetype=self.mimetype
       ^^^^^^^^^^^^^^^^^^^^^^^^^^^^
  File "/home/dominic-source/Projects/venv/lib/python3.11/site-packages/flask/json/provider.py", line 179, in dumps
    return json.dumps(obj, **kwargs)
           ^^^^^^^^^^^^^^^^^^^^^^^^^
  File "/usr/lib/python3.11/json/__init__.py", line 238, in dumps
    **kw).encode(obj)
          ^^^^^^^^^^^
  File "/usr/lib/python3.11/json/encoder.py", line 200, in encode
    chunks = self.iterencode(o, _one_shot=True)
             ^^^^^^^^^^^^^^^^^^^^^^^^^^^^^^^^^^
  File "/usr/lib/python3.11/json/encoder.py", line 258, in iterencode
    return _iterencode(o, 0)
           ^^^^^^^^^^^^^^^^^
  File "/home/dominic-source/Projects/venv/lib/python3.11/site-packages/flask/json/provider.py", line 121, in _default
    raise TypeError(f"Object of type {type(o).__name__} is not JSON serializable")
TypeError: Object of type Category is not JSON serializable
2024-05-10 15:41:35,752 - ERROR - Error occured:
Traceback (most recent call last):
  File "/home/dominic-source/Projects/Home_Deliverer/flask_server/views/v1/category.py", line 54, in get_category
    return jsonify(category.scaler()), 200
                   ^^^^^^^^^^^^^^^
AttributeError: 'Category' object has no attribute 'scaler'
2024-05-10 15:45:19,271 - ERROR - Error occured:
Traceback (most recent call last):
  File "/home/dominic-source/Projects/Home_Deliverer/flask_server/views/v1/category.py", line 55, in get_category
    return jsonify(category.__dict__), 200
           ^^^^^^^^^^^^^^^^^^^^^^^^^^
  File "/home/dominic-source/Projects/venv/lib/python3.11/site-packages/flask/json/__init__.py", line 170, in jsonify
    return current_app.json.response(*args, **kwargs)  # type: ignore[return-value]
           ^^^^^^^^^^^^^^^^^^^^^^^^^^^^^^^^^^^^^^^^^^
  File "/home/dominic-source/Projects/venv/lib/python3.11/site-packages/flask/json/provider.py", line 214, in response
    f"{self.dumps(obj, **dump_args)}\n", mimetype=self.mimetype
       ^^^^^^^^^^^^^^^^^^^^^^^^^^^^
  File "/home/dominic-source/Projects/venv/lib/python3.11/site-packages/flask/json/provider.py", line 179, in dumps
    return json.dumps(obj, **kwargs)
           ^^^^^^^^^^^^^^^^^^^^^^^^^
  File "/usr/lib/python3.11/json/__init__.py", line 238, in dumps
    **kw).encode(obj)
          ^^^^^^^^^^^
  File "/usr/lib/python3.11/json/encoder.py", line 200, in encode
    chunks = self.iterencode(o, _one_shot=True)
             ^^^^^^^^^^^^^^^^^^^^^^^^^^^^^^^^^^
  File "/usr/lib/python3.11/json/encoder.py", line 258, in iterencode
    return _iterencode(o, 0)
           ^^^^^^^^^^^^^^^^^
  File "/home/dominic-source/Projects/venv/lib/python3.11/site-packages/flask/json/provider.py", line 121, in _default
    raise TypeError(f"Object of type {type(o).__name__} is not JSON serializable")
TypeError: Object of type InstanceState is not JSON serializable
2024-05-10 15:46:11,105 - ERROR - Error occured:
Traceback (most recent call last):
  File "/home/dominic-source/Projects/Home_Deliverer/flask_server/views/v1/category.py", line 56, in get_category
    return jsonify(category.__dict__), 200
           ^^^^^^^^^^^^^^^^^^^^^^^^^^
  File "/home/dominic-source/Projects/venv/lib/python3.11/site-packages/flask/json/__init__.py", line 170, in jsonify
    return current_app.json.response(*args, **kwargs)  # type: ignore[return-value]
           ^^^^^^^^^^^^^^^^^^^^^^^^^^^^^^^^^^^^^^^^^^
  File "/home/dominic-source/Projects/venv/lib/python3.11/site-packages/flask/json/provider.py", line 214, in response
    f"{self.dumps(obj, **dump_args)}\n", mimetype=self.mimetype
       ^^^^^^^^^^^^^^^^^^^^^^^^^^^^
  File "/home/dominic-source/Projects/venv/lib/python3.11/site-packages/flask/json/provider.py", line 179, in dumps
    return json.dumps(obj, **kwargs)
           ^^^^^^^^^^^^^^^^^^^^^^^^^
  File "/usr/lib/python3.11/json/__init__.py", line 238, in dumps
    **kw).encode(obj)
          ^^^^^^^^^^^
  File "/usr/lib/python3.11/json/encoder.py", line 200, in encode
    chunks = self.iterencode(o, _one_shot=True)
             ^^^^^^^^^^^^^^^^^^^^^^^^^^^^^^^^^^
  File "/usr/lib/python3.11/json/encoder.py", line 258, in iterencode
    return _iterencode(o, 0)
           ^^^^^^^^^^^^^^^^^
  File "/home/dominic-source/Projects/venv/lib/python3.11/site-packages/flask/json/provider.py", line 121, in _default
    raise TypeError(f"Object of type {type(o).__name__} is not JSON serializable")
TypeError: Object of type InstanceState is not JSON serializable
2024-05-10 15:58:37,364 - ERROR - Error occured:
Traceback (most recent call last):
  File "/home/dominic-source/Projects/venv/lib/python3.11/site-packages/sqlalchemy/engine/base.py", line 1970, in _exec_single_context
    self.dialect.do_execute(
  File "/home/dominic-source/Projects/venv/lib/python3.11/site-packages/sqlalchemy/engine/default.py", line 924, in do_execute
    cursor.execute(statement, parameters)
sqlite3.IntegrityError: UNIQUE constraint failed: category.name

The above exception was the direct cause of the following exception:

Traceback (most recent call last):
  File "/home/dominic-source/Projects/Home_Deliverer/flask_server/views/v1/category.py", line 19, in create_category
    db.session.commit()
  File "/home/dominic-source/Projects/venv/lib/python3.11/site-packages/sqlalchemy/orm/scoping.py", line 597, in commit
    return self._proxied.commit()
           ^^^^^^^^^^^^^^^^^^^^^^
  File "/home/dominic-source/Projects/venv/lib/python3.11/site-packages/sqlalchemy/orm/session.py", line 1972, in commit
    trans.commit(_to_root=True)
  File "<string>", line 2, in commit
  File "/home/dominic-source/Projects/venv/lib/python3.11/site-packages/sqlalchemy/orm/state_changes.py", line 139, in _go
    ret_value = fn(self, *arg, **kw)
                ^^^^^^^^^^^^^^^^^^^^
  File "/home/dominic-source/Projects/venv/lib/python3.11/site-packages/sqlalchemy/orm/session.py", line 1257, in commit
    self._prepare_impl()
  File "<string>", line 2, in _prepare_impl
  File "/home/dominic-source/Projects/venv/lib/python3.11/site-packages/sqlalchemy/orm/state_changes.py", line 139, in _go
    ret_value = fn(self, *arg, **kw)
                ^^^^^^^^^^^^^^^^^^^^
  File "/home/dominic-source/Projects/venv/lib/python3.11/site-packages/sqlalchemy/orm/session.py", line 1232, in _prepare_impl
    self.session.flush()
  File "/home/dominic-source/Projects/venv/lib/python3.11/site-packages/sqlalchemy/orm/session.py", line 4296, in flush
    self._flush(objects)
  File "/home/dominic-source/Projects/venv/lib/python3.11/site-packages/sqlalchemy/orm/session.py", line 4431, in _flush
    with util.safe_reraise():
  File "/home/dominic-source/Projects/venv/lib/python3.11/site-packages/sqlalchemy/util/langhelpers.py", line 146, in __exit__
    raise exc_value.with_traceback(exc_tb)
  File "/home/dominic-source/Projects/venv/lib/python3.11/site-packages/sqlalchemy/orm/session.py", line 4392, in _flush
    flush_context.execute()
  File "/home/dominic-source/Projects/venv/lib/python3.11/site-packages/sqlalchemy/orm/unitofwork.py", line 466, in execute
    rec.execute(self)
  File "/home/dominic-source/Projects/venv/lib/python3.11/site-packages/sqlalchemy/orm/unitofwork.py", line 642, in execute
    util.preloaded.orm_persistence.save_obj(
  File "/home/dominic-source/Projects/venv/lib/python3.11/site-packages/sqlalchemy/orm/persistence.py", line 93, in save_obj
    _emit_insert_statements(
  File "/home/dominic-source/Projects/venv/lib/python3.11/site-packages/sqlalchemy/orm/persistence.py", line 1233, in _emit_insert_statements
    result = connection.execute(
             ^^^^^^^^^^^^^^^^^^^
  File "/home/dominic-source/Projects/venv/lib/python3.11/site-packages/sqlalchemy/engine/base.py", line 1421, in execute
    return meth(
           ^^^^^
  File "/home/dominic-source/Projects/venv/lib/python3.11/site-packages/sqlalchemy/sql/elements.py", line 514, in _execute_on_connection
    return connection._execute_clauseelement(
           ^^^^^^^^^^^^^^^^^^^^^^^^^^^^^^^^^^
  File "/home/dominic-source/Projects/venv/lib/python3.11/site-packages/sqlalchemy/engine/base.py", line 1643, in _execute_clauseelement
    ret = self._execute_context(
          ^^^^^^^^^^^^^^^^^^^^^^
  File "/home/dominic-source/Projects/venv/lib/python3.11/site-packages/sqlalchemy/engine/base.py", line 1849, in _execute_context
    return self._exec_single_context(
           ^^^^^^^^^^^^^^^^^^^^^^^^^^
  File "/home/dominic-source/Projects/venv/lib/python3.11/site-packages/sqlalchemy/engine/base.py", line 1989, in _exec_single_context
    self._handle_dbapi_exception(
  File "/home/dominic-source/Projects/venv/lib/python3.11/site-packages/sqlalchemy/engine/base.py", line 2356, in _handle_dbapi_exception
    raise sqlalchemy_exception.with_traceback(exc_info[2]) from e
  File "/home/dominic-source/Projects/venv/lib/python3.11/site-packages/sqlalchemy/engine/base.py", line 1970, in _exec_single_context
    self.dialect.do_execute(
  File "/home/dominic-source/Projects/venv/lib/python3.11/site-packages/sqlalchemy/engine/default.py", line 924, in do_execute
    cursor.execute(statement, parameters)
sqlalchemy.exc.IntegrityError: (sqlite3.IntegrityError) UNIQUE constraint failed: category.name
[SQL: INSERT INTO category (name) VALUES (?)]
[parameters: ('Consumable Products | Food & Beverages | Staples (Rice, Flour, Pasta)',)]
(Background on this error at: https://sqlalche.me/e/20/gkpj)
2024-05-10 15:59:23,418 - ERROR - Error occured:
Traceback (most recent call last):
  File "/home/dominic-source/Projects/venv/lib/python3.11/site-packages/sqlalchemy/engine/base.py", line 1970, in _exec_single_context
    self.dialect.do_execute(
  File "/home/dominic-source/Projects/venv/lib/python3.11/site-packages/sqlalchemy/engine/default.py", line 924, in do_execute
    cursor.execute(statement, parameters)
sqlite3.IntegrityError: UNIQUE constraint failed: category.name

The above exception was the direct cause of the following exception:

Traceback (most recent call last):
  File "/home/dominic-source/Projects/Home_Deliverer/flask_server/views/v1/category.py", line 19, in create_category
    db.session.commit()
  File "/home/dominic-source/Projects/venv/lib/python3.11/site-packages/sqlalchemy/orm/scoping.py", line 597, in commit
    return self._proxied.commit()
           ^^^^^^^^^^^^^^^^^^^^^^
  File "/home/dominic-source/Projects/venv/lib/python3.11/site-packages/sqlalchemy/orm/session.py", line 1972, in commit
    trans.commit(_to_root=True)
  File "<string>", line 2, in commit
  File "/home/dominic-source/Projects/venv/lib/python3.11/site-packages/sqlalchemy/orm/state_changes.py", line 139, in _go
    ret_value = fn(self, *arg, **kw)
                ^^^^^^^^^^^^^^^^^^^^
  File "/home/dominic-source/Projects/venv/lib/python3.11/site-packages/sqlalchemy/orm/session.py", line 1257, in commit
    self._prepare_impl()
  File "<string>", line 2, in _prepare_impl
  File "/home/dominic-source/Projects/venv/lib/python3.11/site-packages/sqlalchemy/orm/state_changes.py", line 139, in _go
    ret_value = fn(self, *arg, **kw)
                ^^^^^^^^^^^^^^^^^^^^
  File "/home/dominic-source/Projects/venv/lib/python3.11/site-packages/sqlalchemy/orm/session.py", line 1232, in _prepare_impl
    self.session.flush()
  File "/home/dominic-source/Projects/venv/lib/python3.11/site-packages/sqlalchemy/orm/session.py", line 4296, in flush
    self._flush(objects)
  File "/home/dominic-source/Projects/venv/lib/python3.11/site-packages/sqlalchemy/orm/session.py", line 4431, in _flush
    with util.safe_reraise():
  File "/home/dominic-source/Projects/venv/lib/python3.11/site-packages/sqlalchemy/util/langhelpers.py", line 146, in __exit__
    raise exc_value.with_traceback(exc_tb)
  File "/home/dominic-source/Projects/venv/lib/python3.11/site-packages/sqlalchemy/orm/session.py", line 4392, in _flush
    flush_context.execute()
  File "/home/dominic-source/Projects/venv/lib/python3.11/site-packages/sqlalchemy/orm/unitofwork.py", line 466, in execute
    rec.execute(self)
  File "/home/dominic-source/Projects/venv/lib/python3.11/site-packages/sqlalchemy/orm/unitofwork.py", line 642, in execute
    util.preloaded.orm_persistence.save_obj(
  File "/home/dominic-source/Projects/venv/lib/python3.11/site-packages/sqlalchemy/orm/persistence.py", line 93, in save_obj
    _emit_insert_statements(
  File "/home/dominic-source/Projects/venv/lib/python3.11/site-packages/sqlalchemy/orm/persistence.py", line 1233, in _emit_insert_statements
    result = connection.execute(
             ^^^^^^^^^^^^^^^^^^^
  File "/home/dominic-source/Projects/venv/lib/python3.11/site-packages/sqlalchemy/engine/base.py", line 1421, in execute
    return meth(
           ^^^^^
  File "/home/dominic-source/Projects/venv/lib/python3.11/site-packages/sqlalchemy/sql/elements.py", line 514, in _execute_on_connection
    return connection._execute_clauseelement(
           ^^^^^^^^^^^^^^^^^^^^^^^^^^^^^^^^^^
  File "/home/dominic-source/Projects/venv/lib/python3.11/site-packages/sqlalchemy/engine/base.py", line 1643, in _execute_clauseelement
    ret = self._execute_context(
          ^^^^^^^^^^^^^^^^^^^^^^
  File "/home/dominic-source/Projects/venv/lib/python3.11/site-packages/sqlalchemy/engine/base.py", line 1849, in _execute_context
    return self._exec_single_context(
           ^^^^^^^^^^^^^^^^^^^^^^^^^^
  File "/home/dominic-source/Projects/venv/lib/python3.11/site-packages/sqlalchemy/engine/base.py", line 1989, in _exec_single_context
    self._handle_dbapi_exception(
  File "/home/dominic-source/Projects/venv/lib/python3.11/site-packages/sqlalchemy/engine/base.py", line 2356, in _handle_dbapi_exception
    raise sqlalchemy_exception.with_traceback(exc_info[2]) from e
  File "/home/dominic-source/Projects/venv/lib/python3.11/site-packages/sqlalchemy/engine/base.py", line 1970, in _exec_single_context
    self.dialect.do_execute(
  File "/home/dominic-source/Projects/venv/lib/python3.11/site-packages/sqlalchemy/engine/default.py", line 924, in do_execute
    cursor.execute(statement, parameters)
sqlalchemy.exc.IntegrityError: (sqlite3.IntegrityError) UNIQUE constraint failed: category.name
[SQL: INSERT INTO category (name) VALUES (?)]
[parameters: ('Consumable Products | Food & Beverages | Staples (Rice, Flour, Pasta)',)]
(Background on this error at: https://sqlalche.me/e/20/gkpj)
2024-05-10 15:59:35,824 - ERROR - Error occured:
Traceback (most recent call last):
  File "/home/dominic-source/Projects/venv/lib/python3.11/site-packages/sqlalchemy/engine/base.py", line 1970, in _exec_single_context
    self.dialect.do_execute(
  File "/home/dominic-source/Projects/venv/lib/python3.11/site-packages/sqlalchemy/engine/default.py", line 924, in do_execute
    cursor.execute(statement, parameters)
sqlite3.IntegrityError: UNIQUE constraint failed: category.name

The above exception was the direct cause of the following exception:

Traceback (most recent call last):
  File "/home/dominic-source/Projects/Home_Deliverer/flask_server/views/v1/category.py", line 19, in create_category
    db.session.commit()
  File "/home/dominic-source/Projects/venv/lib/python3.11/site-packages/sqlalchemy/orm/scoping.py", line 597, in commit
    return self._proxied.commit()
           ^^^^^^^^^^^^^^^^^^^^^^
  File "/home/dominic-source/Projects/venv/lib/python3.11/site-packages/sqlalchemy/orm/session.py", line 1972, in commit
    trans.commit(_to_root=True)
  File "<string>", line 2, in commit
  File "/home/dominic-source/Projects/venv/lib/python3.11/site-packages/sqlalchemy/orm/state_changes.py", line 139, in _go
    ret_value = fn(self, *arg, **kw)
                ^^^^^^^^^^^^^^^^^^^^
  File "/home/dominic-source/Projects/venv/lib/python3.11/site-packages/sqlalchemy/orm/session.py", line 1257, in commit
    self._prepare_impl()
  File "<string>", line 2, in _prepare_impl
  File "/home/dominic-source/Projects/venv/lib/python3.11/site-packages/sqlalchemy/orm/state_changes.py", line 139, in _go
    ret_value = fn(self, *arg, **kw)
                ^^^^^^^^^^^^^^^^^^^^
  File "/home/dominic-source/Projects/venv/lib/python3.11/site-packages/sqlalchemy/orm/session.py", line 1232, in _prepare_impl
    self.session.flush()
  File "/home/dominic-source/Projects/venv/lib/python3.11/site-packages/sqlalchemy/orm/session.py", line 4296, in flush
    self._flush(objects)
  File "/home/dominic-source/Projects/venv/lib/python3.11/site-packages/sqlalchemy/orm/session.py", line 4431, in _flush
    with util.safe_reraise():
  File "/home/dominic-source/Projects/venv/lib/python3.11/site-packages/sqlalchemy/util/langhelpers.py", line 146, in __exit__
    raise exc_value.with_traceback(exc_tb)
  File "/home/dominic-source/Projects/venv/lib/python3.11/site-packages/sqlalchemy/orm/session.py", line 4392, in _flush
    flush_context.execute()
  File "/home/dominic-source/Projects/venv/lib/python3.11/site-packages/sqlalchemy/orm/unitofwork.py", line 466, in execute
    rec.execute(self)
  File "/home/dominic-source/Projects/venv/lib/python3.11/site-packages/sqlalchemy/orm/unitofwork.py", line 642, in execute
    util.preloaded.orm_persistence.save_obj(
  File "/home/dominic-source/Projects/venv/lib/python3.11/site-packages/sqlalchemy/orm/persistence.py", line 93, in save_obj
    _emit_insert_statements(
  File "/home/dominic-source/Projects/venv/lib/python3.11/site-packages/sqlalchemy/orm/persistence.py", line 1233, in _emit_insert_statements
    result = connection.execute(
             ^^^^^^^^^^^^^^^^^^^
  File "/home/dominic-source/Projects/venv/lib/python3.11/site-packages/sqlalchemy/engine/base.py", line 1421, in execute
    return meth(
           ^^^^^
  File "/home/dominic-source/Projects/venv/lib/python3.11/site-packages/sqlalchemy/sql/elements.py", line 514, in _execute_on_connection
    return connection._execute_clauseelement(
           ^^^^^^^^^^^^^^^^^^^^^^^^^^^^^^^^^^
  File "/home/dominic-source/Projects/venv/lib/python3.11/site-packages/sqlalchemy/engine/base.py", line 1643, in _execute_clauseelement
    ret = self._execute_context(
          ^^^^^^^^^^^^^^^^^^^^^^
  File "/home/dominic-source/Projects/venv/lib/python3.11/site-packages/sqlalchemy/engine/base.py", line 1849, in _execute_context
    return self._exec_single_context(
           ^^^^^^^^^^^^^^^^^^^^^^^^^^
  File "/home/dominic-source/Projects/venv/lib/python3.11/site-packages/sqlalchemy/engine/base.py", line 1989, in _exec_single_context
    self._handle_dbapi_exception(
  File "/home/dominic-source/Projects/venv/lib/python3.11/site-packages/sqlalchemy/engine/base.py", line 2356, in _handle_dbapi_exception
    raise sqlalchemy_exception.with_traceback(exc_info[2]) from e
  File "/home/dominic-source/Projects/venv/lib/python3.11/site-packages/sqlalchemy/engine/base.py", line 1970, in _exec_single_context
    self.dialect.do_execute(
  File "/home/dominic-source/Projects/venv/lib/python3.11/site-packages/sqlalchemy/engine/default.py", line 924, in do_execute
    cursor.execute(statement, parameters)
sqlalchemy.exc.IntegrityError: (sqlite3.IntegrityError) UNIQUE constraint failed: category.name
[SQL: INSERT INTO category (name) VALUES (?)]
[parameters: ('Consumable Products | Food & Beverages | Staples (Rice, Flour, Pasta)',)]
(Background on this error at: https://sqlalche.me/e/20/gkpj)
2024-05-10 16:13:36,372 - ERROR - Error occured:
Traceback (most recent call last):
  File "/home/dominic-source/Projects/venv/lib/python3.11/site-packages/sqlalchemy/engine/base.py", line 1970, in _exec_single_context
    self.dialect.do_execute(
  File "/home/dominic-source/Projects/venv/lib/python3.11/site-packages/sqlalchemy/engine/default.py", line 924, in do_execute
    cursor.execute(statement, parameters)
sqlite3.IntegrityError: UNIQUE constraint failed: category.name

The above exception was the direct cause of the following exception:

Traceback (most recent call last):
  File "/home/dominic-source/Projects/Home_Deliverer/flask_server/views/v1/category.py", line 37, in create_category
    db.session.commit()
  File "/home/dominic-source/Projects/venv/lib/python3.11/site-packages/sqlalchemy/orm/scoping.py", line 597, in commit
    return self._proxied.commit()
           ^^^^^^^^^^^^^^^^^^^^^^
  File "/home/dominic-source/Projects/venv/lib/python3.11/site-packages/sqlalchemy/orm/session.py", line 1972, in commit
    trans.commit(_to_root=True)
  File "<string>", line 2, in commit
  File "/home/dominic-source/Projects/venv/lib/python3.11/site-packages/sqlalchemy/orm/state_changes.py", line 139, in _go
    ret_value = fn(self, *arg, **kw)
                ^^^^^^^^^^^^^^^^^^^^
  File "/home/dominic-source/Projects/venv/lib/python3.11/site-packages/sqlalchemy/orm/session.py", line 1257, in commit
    self._prepare_impl()
  File "<string>", line 2, in _prepare_impl
  File "/home/dominic-source/Projects/venv/lib/python3.11/site-packages/sqlalchemy/orm/state_changes.py", line 139, in _go
    ret_value = fn(self, *arg, **kw)
                ^^^^^^^^^^^^^^^^^^^^
  File "/home/dominic-source/Projects/venv/lib/python3.11/site-packages/sqlalchemy/orm/session.py", line 1232, in _prepare_impl
    self.session.flush()
  File "/home/dominic-source/Projects/venv/lib/python3.11/site-packages/sqlalchemy/orm/session.py", line 4296, in flush
    self._flush(objects)
  File "/home/dominic-source/Projects/venv/lib/python3.11/site-packages/sqlalchemy/orm/session.py", line 4431, in _flush
    with util.safe_reraise():
  File "/home/dominic-source/Projects/venv/lib/python3.11/site-packages/sqlalchemy/util/langhelpers.py", line 146, in __exit__
    raise exc_value.with_traceback(exc_tb)
  File "/home/dominic-source/Projects/venv/lib/python3.11/site-packages/sqlalchemy/orm/session.py", line 4392, in _flush
    flush_context.execute()
  File "/home/dominic-source/Projects/venv/lib/python3.11/site-packages/sqlalchemy/orm/unitofwork.py", line 466, in execute
    rec.execute(self)
  File "/home/dominic-source/Projects/venv/lib/python3.11/site-packages/sqlalchemy/orm/unitofwork.py", line 642, in execute
    util.preloaded.orm_persistence.save_obj(
  File "/home/dominic-source/Projects/venv/lib/python3.11/site-packages/sqlalchemy/orm/persistence.py", line 93, in save_obj
    _emit_insert_statements(
  File "/home/dominic-source/Projects/venv/lib/python3.11/site-packages/sqlalchemy/orm/persistence.py", line 1233, in _emit_insert_statements
    result = connection.execute(
             ^^^^^^^^^^^^^^^^^^^
  File "/home/dominic-source/Projects/venv/lib/python3.11/site-packages/sqlalchemy/engine/base.py", line 1421, in execute
    return meth(
           ^^^^^
  File "/home/dominic-source/Projects/venv/lib/python3.11/site-packages/sqlalchemy/sql/elements.py", line 514, in _execute_on_connection
    return connection._execute_clauseelement(
           ^^^^^^^^^^^^^^^^^^^^^^^^^^^^^^^^^^
  File "/home/dominic-source/Projects/venv/lib/python3.11/site-packages/sqlalchemy/engine/base.py", line 1643, in _execute_clauseelement
    ret = self._execute_context(
          ^^^^^^^^^^^^^^^^^^^^^^
  File "/home/dominic-source/Projects/venv/lib/python3.11/site-packages/sqlalchemy/engine/base.py", line 1849, in _execute_context
    return self._exec_single_context(
           ^^^^^^^^^^^^^^^^^^^^^^^^^^
  File "/home/dominic-source/Projects/venv/lib/python3.11/site-packages/sqlalchemy/engine/base.py", line 1989, in _exec_single_context
    self._handle_dbapi_exception(
  File "/home/dominic-source/Projects/venv/lib/python3.11/site-packages/sqlalchemy/engine/base.py", line 2356, in _handle_dbapi_exception
    raise sqlalchemy_exception.with_traceback(exc_info[2]) from e
  File "/home/dominic-source/Projects/venv/lib/python3.11/site-packages/sqlalchemy/engine/base.py", line 1970, in _exec_single_context
    self.dialect.do_execute(
  File "/home/dominic-source/Projects/venv/lib/python3.11/site-packages/sqlalchemy/engine/default.py", line 924, in do_execute
    cursor.execute(statement, parameters)
sqlalchemy.exc.IntegrityError: (sqlite3.IntegrityError) UNIQUE constraint failed: category.name
[SQL: INSERT INTO category (name) VALUES (?)]
[parameters: ('Consumable Products | Food & Beverages | Staples (Rice, Flour, Pasta)',)]
(Background on this error at: https://sqlalche.me/e/20/gkpj)
2024-05-10 16:14:17,657 - ERROR - Error occured:
Traceback (most recent call last):
  File "/home/dominic-source/Projects/venv/lib/python3.11/site-packages/sqlalchemy/engine/base.py", line 1970, in _exec_single_context
    self.dialect.do_execute(
  File "/home/dominic-source/Projects/venv/lib/python3.11/site-packages/sqlalchemy/engine/default.py", line 924, in do_execute
    cursor.execute(statement, parameters)
sqlite3.IntegrityError: UNIQUE constraint failed: category.name

The above exception was the direct cause of the following exception:

Traceback (most recent call last):
  File "/home/dominic-source/Projects/Home_Deliverer/flask_server/views/v1/category.py", line 37, in create_category
    db.session.commit()
  File "/home/dominic-source/Projects/venv/lib/python3.11/site-packages/sqlalchemy/orm/scoping.py", line 597, in commit
    return self._proxied.commit()
           ^^^^^^^^^^^^^^^^^^^^^^
  File "/home/dominic-source/Projects/venv/lib/python3.11/site-packages/sqlalchemy/orm/session.py", line 1972, in commit
    trans.commit(_to_root=True)
  File "<string>", line 2, in commit
  File "/home/dominic-source/Projects/venv/lib/python3.11/site-packages/sqlalchemy/orm/state_changes.py", line 139, in _go
    ret_value = fn(self, *arg, **kw)
                ^^^^^^^^^^^^^^^^^^^^
  File "/home/dominic-source/Projects/venv/lib/python3.11/site-packages/sqlalchemy/orm/session.py", line 1257, in commit
    self._prepare_impl()
  File "<string>", line 2, in _prepare_impl
  File "/home/dominic-source/Projects/venv/lib/python3.11/site-packages/sqlalchemy/orm/state_changes.py", line 139, in _go
    ret_value = fn(self, *arg, **kw)
                ^^^^^^^^^^^^^^^^^^^^
  File "/home/dominic-source/Projects/venv/lib/python3.11/site-packages/sqlalchemy/orm/session.py", line 1232, in _prepare_impl
    self.session.flush()
  File "/home/dominic-source/Projects/venv/lib/python3.11/site-packages/sqlalchemy/orm/session.py", line 4296, in flush
    self._flush(objects)
  File "/home/dominic-source/Projects/venv/lib/python3.11/site-packages/sqlalchemy/orm/session.py", line 4431, in _flush
    with util.safe_reraise():
  File "/home/dominic-source/Projects/venv/lib/python3.11/site-packages/sqlalchemy/util/langhelpers.py", line 146, in __exit__
    raise exc_value.with_traceback(exc_tb)
  File "/home/dominic-source/Projects/venv/lib/python3.11/site-packages/sqlalchemy/orm/session.py", line 4392, in _flush
    flush_context.execute()
  File "/home/dominic-source/Projects/venv/lib/python3.11/site-packages/sqlalchemy/orm/unitofwork.py", line 466, in execute
    rec.execute(self)
  File "/home/dominic-source/Projects/venv/lib/python3.11/site-packages/sqlalchemy/orm/unitofwork.py", line 642, in execute
    util.preloaded.orm_persistence.save_obj(
  File "/home/dominic-source/Projects/venv/lib/python3.11/site-packages/sqlalchemy/orm/persistence.py", line 93, in save_obj
    _emit_insert_statements(
  File "/home/dominic-source/Projects/venv/lib/python3.11/site-packages/sqlalchemy/orm/persistence.py", line 1233, in _emit_insert_statements
    result = connection.execute(
             ^^^^^^^^^^^^^^^^^^^
  File "/home/dominic-source/Projects/venv/lib/python3.11/site-packages/sqlalchemy/engine/base.py", line 1421, in execute
    return meth(
           ^^^^^
  File "/home/dominic-source/Projects/venv/lib/python3.11/site-packages/sqlalchemy/sql/elements.py", line 514, in _execute_on_connection
    return connection._execute_clauseelement(
           ^^^^^^^^^^^^^^^^^^^^^^^^^^^^^^^^^^
  File "/home/dominic-source/Projects/venv/lib/python3.11/site-packages/sqlalchemy/engine/base.py", line 1643, in _execute_clauseelement
    ret = self._execute_context(
          ^^^^^^^^^^^^^^^^^^^^^^
  File "/home/dominic-source/Projects/venv/lib/python3.11/site-packages/sqlalchemy/engine/base.py", line 1849, in _execute_context
    return self._exec_single_context(
           ^^^^^^^^^^^^^^^^^^^^^^^^^^
  File "/home/dominic-source/Projects/venv/lib/python3.11/site-packages/sqlalchemy/engine/base.py", line 1989, in _exec_single_context
    self._handle_dbapi_exception(
  File "/home/dominic-source/Projects/venv/lib/python3.11/site-packages/sqlalchemy/engine/base.py", line 2356, in _handle_dbapi_exception
    raise sqlalchemy_exception.with_traceback(exc_info[2]) from e
  File "/home/dominic-source/Projects/venv/lib/python3.11/site-packages/sqlalchemy/engine/base.py", line 1970, in _exec_single_context
    self.dialect.do_execute(
  File "/home/dominic-source/Projects/venv/lib/python3.11/site-packages/sqlalchemy/engine/default.py", line 924, in do_execute
    cursor.execute(statement, parameters)
sqlalchemy.exc.IntegrityError: (sqlite3.IntegrityError) UNIQUE constraint failed: category.name
[SQL: INSERT INTO category (name) VALUES (?)]
[parameters: ('Consumable Products | Food & Beverages | Staples (Rice, Flour, Pasta)',)]
(Background on this error at: https://sqlalche.me/e/20/gkpj)
2024-05-13 12:32:59,175 - ERROR - Error occured:
Traceback (most recent call last):
  File "/home/dominic-source/Projects/Home_Deliverer/flask_server/views/v1/product.py", line 14, in create_product
    name = request.form.get(name, None)
                            ^^^^
UnboundLocalError: cannot access local variable 'name' where it is not associated with a value
2024-05-13 12:33:38,494 - ERROR - Error occured:
Traceback (most recent call last):
  File "/home/dominic-source/Projects/Home_Deliverer/flask_server/views/v1/product.py", line 14, in create_product
    name = request.form.get(name, None)
                            ^^^^
UnboundLocalError: cannot access local variable 'name' where it is not associated with a value
2024-05-13 12:37:29,475 - ERROR - Error occured:
Traceback (most recent call last):
  File "/home/dominic-source/Projects/Home_Deliverer/flask_server/views/v1/product.py", line 14, in create_product
    name = request.form.get(name, None)
                            ^^^^
UnboundLocalError: cannot access local variable 'name' where it is not associated with a value
2024-05-13 12:37:50,553 - ERROR - Error occured:
Traceback (most recent call last):
  File "/home/dominic-source/Projects/Home_Deliverer/flask_server/views/v1/product.py", line 14, in create_product
    name = request.form.get(name, None)
                            ^^^^
UnboundLocalError: cannot access local variable 'name' where it is not associated with a value
2024-05-13 12:38:56,514 - ERROR - Error occured:
Traceback (most recent call last):
  File "/home/dominic-source/Projects/Home_Deliverer/flask_server/views/v1/product.py", line 21, in create_product
    category = Category.query.filter_by(id=category_id).one()
               ^^^^^^^^^^^^^^^^^^^^^^^^^^^^^^^^^^^^^^^^^^^^^^
  File "/home/dominic-source/Projects/venv/lib/python3.11/site-packages/sqlalchemy/orm/query.py", line 2778, in one
    return self._iter().one()  # type: ignore
           ^^^^^^^^^^^^^^^^^^
  File "/home/dominic-source/Projects/venv/lib/python3.11/site-packages/sqlalchemy/engine/result.py", line 1810, in one
    return self._only_one_row(
           ^^^^^^^^^^^^^^^^^^^
  File "/home/dominic-source/Projects/venv/lib/python3.11/site-packages/sqlalchemy/engine/result.py", line 752, in _only_one_row
    raise exc.NoResultFound(
sqlalchemy.exc.NoResultFound: No row was found when one was required
2024-05-13 13:44:34,716 - ERROR - Error occured:
Traceback (most recent call last):
  File "/home/dominic-source/Projects/Home_Deliverer/flask_server/views/v1/product.py", line 95, in create_product
    category = Category.query.filter_by(id=category_id).one()
               ^^^^^^^^^^^^^^^^^^^^^^^^^^^^^^^^^^^^^^^^^^^^^^
  File "/home/dominic-source/Projects/venv/lib/python3.11/site-packages/sqlalchemy/orm/query.py", line 2778, in one
    return self._iter().one()  # type: ignore
           ^^^^^^^^^^^^^^^^^^
  File "/home/dominic-source/Projects/venv/lib/python3.11/site-packages/sqlalchemy/engine/result.py", line 1810, in one
    return self._only_one_row(
           ^^^^^^^^^^^^^^^^^^^
  File "/home/dominic-source/Projects/venv/lib/python3.11/site-packages/sqlalchemy/engine/result.py", line 752, in _only_one_row
    raise exc.NoResultFound(
sqlalchemy.exc.NoResultFound: No row was found when one was required
2024-05-13 13:44:35,929 - ERROR - Error occured:
Traceback (most recent call last):
  File "/home/dominic-source/Projects/Home_Deliverer/flask_server/views/v1/product.py", line 95, in create_product
    category = Category.query.filter_by(id=category_id).one()
               ^^^^^^^^^^^^^^^^^^^^^^^^^^^^^^^^^^^^^^^^^^^^^^
  File "/home/dominic-source/Projects/venv/lib/python3.11/site-packages/sqlalchemy/orm/query.py", line 2778, in one
    return self._iter().one()  # type: ignore
           ^^^^^^^^^^^^^^^^^^
  File "/home/dominic-source/Projects/venv/lib/python3.11/site-packages/sqlalchemy/engine/result.py", line 1810, in one
    return self._only_one_row(
           ^^^^^^^^^^^^^^^^^^^
  File "/home/dominic-source/Projects/venv/lib/python3.11/site-packages/sqlalchemy/engine/result.py", line 752, in _only_one_row
    raise exc.NoResultFound(
sqlalchemy.exc.NoResultFound: No row was found when one was required
2024-05-13 13:51:17,380 - ERROR - Error occured:
Traceback (most recent call last):
  File "/home/dominic-source/Projects/venv/lib/python3.11/site-packages/sqlalchemy/engine/base.py", line 1970, in _exec_single_context
    self.dialect.do_execute(
  File "/home/dominic-source/Projects/venv/lib/python3.11/site-packages/sqlalchemy/engine/default.py", line 924, in do_execute
    cursor.execute(statement, parameters)
sqlite3.IntegrityError: CHECK constraint failed: currency IN ('Naira', 'Dollar')

The above exception was the direct cause of the following exception:

Traceback (most recent call last):
  File "/home/dominic-source/Projects/Home_Deliverer/flask_server/views/v1/product.py", line 39, in update_products
    db.session.commit()
  File "/home/dominic-source/Projects/venv/lib/python3.11/site-packages/sqlalchemy/orm/scoping.py", line 597, in commit
    return self._proxied.commit()
           ^^^^^^^^^^^^^^^^^^^^^^
  File "/home/dominic-source/Projects/venv/lib/python3.11/site-packages/sqlalchemy/orm/session.py", line 1972, in commit
    trans.commit(_to_root=True)
  File "<string>", line 2, in commit
  File "/home/dominic-source/Projects/venv/lib/python3.11/site-packages/sqlalchemy/orm/state_changes.py", line 139, in _go
    ret_value = fn(self, *arg, **kw)
                ^^^^^^^^^^^^^^^^^^^^
  File "/home/dominic-source/Projects/venv/lib/python3.11/site-packages/sqlalchemy/orm/session.py", line 1257, in commit
    self._prepare_impl()
  File "<string>", line 2, in _prepare_impl
  File "/home/dominic-source/Projects/venv/lib/python3.11/site-packages/sqlalchemy/orm/state_changes.py", line 139, in _go
    ret_value = fn(self, *arg, **kw)
                ^^^^^^^^^^^^^^^^^^^^
  File "/home/dominic-source/Projects/venv/lib/python3.11/site-packages/sqlalchemy/orm/session.py", line 1232, in _prepare_impl
    self.session.flush()
  File "/home/dominic-source/Projects/venv/lib/python3.11/site-packages/sqlalchemy/orm/session.py", line 4296, in flush
    self._flush(objects)
  File "/home/dominic-source/Projects/venv/lib/python3.11/site-packages/sqlalchemy/orm/session.py", line 4431, in _flush
    with util.safe_reraise():
  File "/home/dominic-source/Projects/venv/lib/python3.11/site-packages/sqlalchemy/util/langhelpers.py", line 146, in __exit__
    raise exc_value.with_traceback(exc_tb)
  File "/home/dominic-source/Projects/venv/lib/python3.11/site-packages/sqlalchemy/orm/session.py", line 4392, in _flush
    flush_context.execute()
  File "/home/dominic-source/Projects/venv/lib/python3.11/site-packages/sqlalchemy/orm/unitofwork.py", line 466, in execute
    rec.execute(self)
  File "/home/dominic-source/Projects/venv/lib/python3.11/site-packages/sqlalchemy/orm/unitofwork.py", line 642, in execute
    util.preloaded.orm_persistence.save_obj(
  File "/home/dominic-source/Projects/venv/lib/python3.11/site-packages/sqlalchemy/orm/persistence.py", line 85, in save_obj
    _emit_update_statements(
  File "/home/dominic-source/Projects/venv/lib/python3.11/site-packages/sqlalchemy/orm/persistence.py", line 912, in _emit_update_statements
    c = connection.execute(
        ^^^^^^^^^^^^^^^^^^^
  File "/home/dominic-source/Projects/venv/lib/python3.11/site-packages/sqlalchemy/engine/base.py", line 1421, in execute
    return meth(
           ^^^^^
  File "/home/dominic-source/Projects/venv/lib/python3.11/site-packages/sqlalchemy/sql/elements.py", line 514, in _execute_on_connection
    return connection._execute_clauseelement(
           ^^^^^^^^^^^^^^^^^^^^^^^^^^^^^^^^^^
  File "/home/dominic-source/Projects/venv/lib/python3.11/site-packages/sqlalchemy/engine/base.py", line 1643, in _execute_clauseelement
    ret = self._execute_context(
          ^^^^^^^^^^^^^^^^^^^^^^
  File "/home/dominic-source/Projects/venv/lib/python3.11/site-packages/sqlalchemy/engine/base.py", line 1849, in _execute_context
    return self._exec_single_context(
           ^^^^^^^^^^^^^^^^^^^^^^^^^^
  File "/home/dominic-source/Projects/venv/lib/python3.11/site-packages/sqlalchemy/engine/base.py", line 1989, in _exec_single_context
    self._handle_dbapi_exception(
  File "/home/dominic-source/Projects/venv/lib/python3.11/site-packages/sqlalchemy/engine/base.py", line 2356, in _handle_dbapi_exception
    raise sqlalchemy_exception.with_traceback(exc_info[2]) from e
  File "/home/dominic-source/Projects/venv/lib/python3.11/site-packages/sqlalchemy/engine/base.py", line 1970, in _exec_single_context
    self.dialect.do_execute(
  File "/home/dominic-source/Projects/venv/lib/python3.11/site-packages/sqlalchemy/engine/default.py", line 924, in do_execute
    cursor.execute(statement, parameters)
sqlalchemy.exc.IntegrityError: (sqlite3.IntegrityError) CHECK constraint failed: currency IN ('Naira', 'Dollar')
[SQL: UPDATE product SET name=?, updated_at=?, price=?, currency=?, category_id=?, quantity=? WHERE product.id = ?]
[parameters: ('Custard milk and breweries', '2024-05-13 13:51:17.378932', '1300', 'meet', '1', '20', 1)]
(Background on this error at: https://sqlalche.me/e/20/gkpj)
2024-05-13 14:01:21,303 - ERROR - Error occured:
Traceback (most recent call last):
  File "/home/dominic-source/Projects/Home_Deliverer/flask_server/views/v1/product.py", line 16, in users_products
    product_data = [{'id':product.id, 'name': product.name, 'quantity': product.quantity, 'price': product.price} for product in user.products]
                                                                                                                                 ^^^^^^^^^^^^^
AttributeError: 'Query' object has no attribute 'products'
2024-05-13 14:01:57,109 - ERROR - Error occured:
Traceback (most recent call last):
  File "/home/dominic-source/Projects/Home_Deliverer/flask_server/views/v1/product.py", line 16, in users_products
    product_data = [{'id':product.id, 'name': product.name, 'quantity': product.quantity, 'price': product.price} for product in user.products]
                                                                                                                                 ^^^^^^^^^^^^^
AttributeError: 'Query' object has no attribute 'products'
2024-05-13 14:03:46,654 - ERROR - Error occured:
Traceback (most recent call last):
  File "/home/dominic-source/Projects/Home_Deliverer/flask_server/views/v1/product.py", line 17, in users_products
    product_data = [{'id':product.id, 'name': product.name, 'quantity': product.quantity, 'price': product.price} for product in user.products]
                                                                                                                                 ^^^^^^^^^^^^^
AttributeError: 'Query' object has no attribute 'products'
2024-05-13 14:07:20,658 - ERROR - Error occured:
Traceback (most recent call last):
  File "/home/dominic-source/Projects/Home_Deliverer/flask_server/views/v1/product.py", line 17, in users_products
    product_data = [{'id':product.id, 'name': product.name, 'quantity': product.quantity, 'price': product.price} for product in user.products]
                                                                                                                                 ^^^^^^^^^^^^^
AttributeError: 'Query' object has no attribute 'products'
2024-05-13 14:33:00,612 - ERROR - Error occured:
Traceback (most recent call last):
  File "/home/dominic-source/Projects/Home_Deliverer/flask_server/views/v1/product.py", line 17, in users_products
    product_data = [{'id':product.id, 'name': product.name, 'quantity': product.quantity, 'price': product.price} for product in user.products]
                                                                                                                                 ^^^^^^^^^^^^^
AttributeError: 'Query' object has no attribute 'products'
2024-05-13 14:36:22,510 - ERROR - Error occured:
Traceback (most recent call last):
  File "/home/dominic-source/Projects/Home_Deliverer/flask_server/views/v1/product.py", line 16, in users_products
    product = db.session.query(Product).filter_by(user_id = user.id).all()
                                                            ^^^^^^^
AttributeError: 'Query' object has no attribute 'id'
2024-05-13 14:50:40,112 - ERROR - Error occured:
Traceback (most recent call last):
  File "/home/dominic-source/Projects/venv/lib/python3.11/site-packages/sqlalchemy/engine/result.py", line 199, in _key_not_found
    self._key_fallback(key, None)
  File "/home/dominic-source/Projects/venv/lib/python3.11/site-packages/sqlalchemy/engine/result.py", line 138, in _key_fallback
    raise KeyError(key) from err
KeyError: 'category_id'

The above exception was the direct cause of the following exception:

Traceback (most recent call last):
  File "/home/dominic-source/Projects/Home_Deliverer/flask_server/views/v1/product.py", line 21, in categories_products
    product_data = [{'category_id': product.category_id, 'id':product.id, 'name': product.name, 'quantity': product.quantity, 'price': product.price} for product in products]
                   ^^^^^^^^^^^^^^^^^^^^^^^^^^^^^^^^^^^^^^^^^^^^^^^^^^^^^^^^^^^^^^^^^^^^^^^^^^^^^^^^^^^^^^^^^^^^^^^^^^^^^^^^^^^^^^^^^^^^^^^^^^^^^^^^^^^^^^^^^^^^^^^^^^^^^^^^^^^
  File "/home/dominic-source/Projects/Home_Deliverer/flask_server/views/v1/product.py", line 21, in <listcomp>
    product_data = [{'category_id': product.category_id, 'id':product.id, 'name': product.name, 'quantity': product.quantity, 'price': product.price} for product in products]
                                    ^^^^^^^^^^^^^^^^^^^
  File "lib/sqlalchemy/cyextension/resultproxy.pyx", line 66, in sqlalchemy.cyextension.resultproxy.BaseRow.__getattr__
  File "lib/sqlalchemy/cyextension/resultproxy.pyx", line 63, in sqlalchemy.cyextension.resultproxy.BaseRow._get_by_key_impl
  File "/home/dominic-source/Projects/venv/lib/python3.11/site-packages/sqlalchemy/engine/result.py", line 201, in _key_not_found
    raise AttributeError(ke.args[0]) from ke
AttributeError: category_id
2024-05-13 14:50:58,623 - ERROR - Error occured:
Traceback (most recent call last):
  File "/home/dominic-source/Projects/venv/lib/python3.11/site-packages/sqlalchemy/engine/result.py", line 199, in _key_not_found
    self._key_fallback(key, None)
  File "/home/dominic-source/Projects/venv/lib/python3.11/site-packages/sqlalchemy/engine/result.py", line 138, in _key_fallback
    raise KeyError(key) from err
KeyError: 'category_id'

The above exception was the direct cause of the following exception:

Traceback (most recent call last):
  File "/home/dominic-source/Projects/Home_Deliverer/flask_server/views/v1/product.py", line 21, in categories_products
    product_data = [{'category_id': product.category_id, 'id':product.id, 'name': product.name, 'quantity': product.quantity, 'price': product.price} for product in products]
                   ^^^^^^^^^^^^^^^^^^^^^^^^^^^^^^^^^^^^^^^^^^^^^^^^^^^^^^^^^^^^^^^^^^^^^^^^^^^^^^^^^^^^^^^^^^^^^^^^^^^^^^^^^^^^^^^^^^^^^^^^^^^^^^^^^^^^^^^^^^^^^^^^^^^^^^^^^^^
  File "/home/dominic-source/Projects/Home_Deliverer/flask_server/views/v1/product.py", line 21, in <listcomp>
    product_data = [{'category_id': product.category_id, 'id':product.id, 'name': product.name, 'quantity': product.quantity, 'price': product.price} for product in products]
                                    ^^^^^^^^^^^^^^^^^^^
  File "lib/sqlalchemy/cyextension/resultproxy.pyx", line 66, in sqlalchemy.cyextension.resultproxy.BaseRow.__getattr__
  File "lib/sqlalchemy/cyextension/resultproxy.pyx", line 63, in sqlalchemy.cyextension.resultproxy.BaseRow._get_by_key_impl
  File "/home/dominic-source/Projects/venv/lib/python3.11/site-packages/sqlalchemy/engine/result.py", line 201, in _key_not_found
    raise AttributeError(ke.args[0]) from ke
AttributeError: category_id
2024-05-13 14:51:32,868 - ERROR - Error occured:
Traceback (most recent call last):
  File "/home/dominic-source/Projects/venv/lib/python3.11/site-packages/sqlalchemy/engine/result.py", line 199, in _key_not_found
    self._key_fallback(key, None)
  File "/home/dominic-source/Projects/venv/lib/python3.11/site-packages/sqlalchemy/engine/result.py", line 138, in _key_fallback
    raise KeyError(key) from err
KeyError: 'category_id'

The above exception was the direct cause of the following exception:

Traceback (most recent call last):
  File "/home/dominic-source/Projects/Home_Deliverer/flask_server/views/v1/product.py", line 21, in categories_products
    product_data = [{'category_id': product.category_id, 'id':product.id, 'name': product.name, 'quantity': product.quantity, 'price': product.price} for product in products]
                   ^^^^^^^^^^^^^^^^^^^^^^^^^^^^^^^^^^^^^^^^^^^^^^^^^^^^^^^^^^^^^^^^^^^^^^^^^^^^^^^^^^^^^^^^^^^^^^^^^^^^^^^^^^^^^^^^^^^^^^^^^^^^^^^^^^^^^^^^^^^^^^^^^^^^^^^^^^^
  File "/home/dominic-source/Projects/Home_Deliverer/flask_server/views/v1/product.py", line 21, in <listcomp>
    product_data = [{'category_id': product.category_id, 'id':product.id, 'name': product.name, 'quantity': product.quantity, 'price': product.price} for product in products]
                                    ^^^^^^^^^^^^^^^^^^^
  File "lib/sqlalchemy/cyextension/resultproxy.pyx", line 66, in sqlalchemy.cyextension.resultproxy.BaseRow.__getattr__
  File "lib/sqlalchemy/cyextension/resultproxy.pyx", line 63, in sqlalchemy.cyextension.resultproxy.BaseRow._get_by_key_impl
  File "/home/dominic-source/Projects/venv/lib/python3.11/site-packages/sqlalchemy/engine/result.py", line 201, in _key_not_found
    raise AttributeError(ke.args[0]) from ke
AttributeError: category_id
2024-05-13 14:56:56,313 - ERROR - Error occured:
Traceback (most recent call last):
  File "/home/dominic-source/Projects/venv/lib/python3.11/site-packages/sqlalchemy/engine/result.py", line 199, in _key_not_found
    self._key_fallback(key, None)
  File "/home/dominic-source/Projects/venv/lib/python3.11/site-packages/sqlalchemy/engine/result.py", line 138, in _key_fallback
    raise KeyError(key) from err
KeyError: 'category_id'

The above exception was the direct cause of the following exception:

Traceback (most recent call last):
  File "/home/dominic-source/Projects/Home_Deliverer/flask_server/views/v1/product.py", line 21, in categories_products
    product_data = [{'name': product.name, 'category_id': product.category_id} for product in products]
                   ^^^^^^^^^^^^^^^^^^^^^^^^^^^^^^^^^^^^^^^^^^^^^^^^^^^^^^^^^^^^^^^^^^^^^^^^^^^^^^^^^^^^
  File "/home/dominic-source/Projects/Home_Deliverer/flask_server/views/v1/product.py", line 21, in <listcomp>
    product_data = [{'name': product.name, 'category_id': product.category_id} for product in products]
                                                          ^^^^^^^^^^^^^^^^^^^
  File "lib/sqlalchemy/cyextension/resultproxy.pyx", line 66, in sqlalchemy.cyextension.resultproxy.BaseRow.__getattr__
  File "lib/sqlalchemy/cyextension/resultproxy.pyx", line 63, in sqlalchemy.cyextension.resultproxy.BaseRow._get_by_key_impl
  File "/home/dominic-source/Projects/venv/lib/python3.11/site-packages/sqlalchemy/engine/result.py", line 201, in _key_not_found
    raise AttributeError(ke.args[0]) from ke
AttributeError: category_id
