2024-05-06 11:19:03,886 - DEBUG - Using selector: EpollSelector
2024-05-06 11:19:03,886 - INFO - Loop 1
2024-05-06 11:19:42,477 - INFO - Received task from queue
2024-05-06 11:19:47,862 - INFO - Email task with user id = 4 is completed!
2024-05-06 11:19:47,863 - INFO - Loop 1
2024-05-06 11:20:44,945 - DEBUG - Using selector: EpollSelector
2024-05-06 11:20:44,945 - INFO - Loop 1
2024-05-06 11:20:54,313 - INFO - Received task from queue
2024-05-06 11:21:03,009 - INFO - Email task with user id = 4 is completed!
2024-05-06 11:21:03,010 - INFO - Loop 1
2024-05-10 12:13:10,290 - ERROR - Error occured:
Traceback (most recent call last):
  File "/home/dominic-source/Projects/Home_Deliverer/flask_server/views/v1/category.py", line 20, in create_category
    return jsonify({'success': category.category_name + ' ' + category.id}), 200
                               ~~~~~~~~~~~~~~~~~~~~~~~~~~~~~^~~~~~~~~~~~~
TypeError: can only concatenate str (not "int") to str
2024-05-10 12:15:13,300 - ERROR - Error occured:
Traceback (most recent call last):
  File "/home/dominic-source/Projects/Home_Deliverer/flask_server/views/v1/category.py", line 20, in create_category
    return jsonify({'success': category.category_name + ' ' + category.id}), 200
                               ~~~~~~~~~~~~~~~~~~~~~~~~~~~~~^~~~~~~~~~~~~
TypeError: can only concatenate str (not "int") to str
2024-05-10 12:21:03,932 - ERROR - Error occured:
Traceback (most recent call last):
  File "/home/dominic-source/Projects/Home_Deliverer/flask_server/views/v1/category.py", line 20, in create_category
    return jsonify({'success': category.category_name + ' ' + category.id}), 200
                               ~~~~~~~~~~~~~~~~~~~~~~~~~~~~~^~~~~~~~~~~~~
TypeError: can only concatenate str (not "int") to str
2024-05-10 15:40:00,902 - ERROR - Error occured:
Traceback (most recent call last):
  File "/home/dominic-source/Projects/Home_Deliverer/flask_server/views/v1/category.py", line 55, in get_category
    return jsonify(category), 200
           ^^^^^^^^^^^^^^^^^
  File "/home/dominic-source/Projects/venv/lib/python3.11/site-packages/flask/json/__init__.py", line 170, in jsonify
    return current_app.json.response(*args, **kwargs)  # type: ignore[return-value]
           ^^^^^^^^^^^^^^^^^^^^^^^^^^^^^^^^^^^^^^^^^^
  File "/home/dominic-source/Projects/venv/lib/python3.11/site-packages/flask/json/provider.py", line 214, in response
    f"{self.dumps(obj, **dump_args)}\n", mimetype=self.mimetype
       ^^^^^^^^^^^^^^^^^^^^^^^^^^^^
  File "/home/dominic-source/Projects/venv/lib/python3.11/site-packages/flask/json/provider.py", line 179, in dumps
    return json.dumps(obj, **kwargs)
           ^^^^^^^^^^^^^^^^^^^^^^^^^
  File "/usr/lib/python3.11/json/__init__.py", line 238, in dumps
    **kw).encode(obj)
          ^^^^^^^^^^^
  File "/usr/lib/python3.11/json/encoder.py", line 200, in encode
    chunks = self.iterencode(o, _one_shot=True)
             ^^^^^^^^^^^^^^^^^^^^^^^^^^^^^^^^^^
  File "/usr/lib/python3.11/json/encoder.py", line 258, in iterencode
    return _iterencode(o, 0)
           ^^^^^^^^^^^^^^^^^
  File "/home/dominic-source/Projects/venv/lib/python3.11/site-packages/flask/json/provider.py", line 121, in _default
    raise TypeError(f"Object of type {type(o).__name__} is not JSON serializable")
TypeError: Object of type Category is not JSON serializable
2024-05-10 15:41:07,504 - ERROR - Error occured:
Traceback (most recent call last):
  File "/home/dominic-source/Projects/Home_Deliverer/flask_server/views/v1/category.py", line 54, in get_category
    return jsonify(category), 200
           ^^^^^^^^^^^^^^^^^
  File "/home/dominic-source/Projects/venv/lib/python3.11/site-packages/flask/json/__init__.py", line 170, in jsonify
    return current_app.json.response(*args, **kwargs)  # type: ignore[return-value]
           ^^^^^^^^^^^^^^^^^^^^^^^^^^^^^^^^^^^^^^^^^^
  File "/home/dominic-source/Projects/venv/lib/python3.11/site-packages/flask/json/provider.py", line 214, in response
    f"{self.dumps(obj, **dump_args)}\n", mimetype=self.mimetype
       ^^^^^^^^^^^^^^^^^^^^^^^^^^^^
  File "/home/dominic-source/Projects/venv/lib/python3.11/site-packages/flask/json/provider.py", line 179, in dumps
    return json.dumps(obj, **kwargs)
           ^^^^^^^^^^^^^^^^^^^^^^^^^
  File "/usr/lib/python3.11/json/__init__.py", line 238, in dumps
    **kw).encode(obj)
          ^^^^^^^^^^^
  File "/usr/lib/python3.11/json/encoder.py", line 200, in encode
    chunks = self.iterencode(o, _one_shot=True)
             ^^^^^^^^^^^^^^^^^^^^^^^^^^^^^^^^^^
  File "/usr/lib/python3.11/json/encoder.py", line 258, in iterencode
    return _iterencode(o, 0)
           ^^^^^^^^^^^^^^^^^
  File "/home/dominic-source/Projects/venv/lib/python3.11/site-packages/flask/json/provider.py", line 121, in _default
    raise TypeError(f"Object of type {type(o).__name__} is not JSON serializable")
TypeError: Object of type Category is not JSON serializable
2024-05-10 15:41:35,752 - ERROR - Error occured:
Traceback (most recent call last):
  File "/home/dominic-source/Projects/Home_Deliverer/flask_server/views/v1/category.py", line 54, in get_category
    return jsonify(category.scaler()), 200
                   ^^^^^^^^^^^^^^^
AttributeError: 'Category' object has no attribute 'scaler'
2024-05-10 15:45:19,271 - ERROR - Error occured:
Traceback (most recent call last):
  File "/home/dominic-source/Projects/Home_Deliverer/flask_server/views/v1/category.py", line 55, in get_category
    return jsonify(category.__dict__), 200
           ^^^^^^^^^^^^^^^^^^^^^^^^^^
  File "/home/dominic-source/Projects/venv/lib/python3.11/site-packages/flask/json/__init__.py", line 170, in jsonify
    return current_app.json.response(*args, **kwargs)  # type: ignore[return-value]
           ^^^^^^^^^^^^^^^^^^^^^^^^^^^^^^^^^^^^^^^^^^
  File "/home/dominic-source/Projects/venv/lib/python3.11/site-packages/flask/json/provider.py", line 214, in response
    f"{self.dumps(obj, **dump_args)}\n", mimetype=self.mimetype
       ^^^^^^^^^^^^^^^^^^^^^^^^^^^^
  File "/home/dominic-source/Projects/venv/lib/python3.11/site-packages/flask/json/provider.py", line 179, in dumps
    return json.dumps(obj, **kwargs)
           ^^^^^^^^^^^^^^^^^^^^^^^^^
  File "/usr/lib/python3.11/json/__init__.py", line 238, in dumps
    **kw).encode(obj)
          ^^^^^^^^^^^
  File "/usr/lib/python3.11/json/encoder.py", line 200, in encode
    chunks = self.iterencode(o, _one_shot=True)
             ^^^^^^^^^^^^^^^^^^^^^^^^^^^^^^^^^^
  File "/usr/lib/python3.11/json/encoder.py", line 258, in iterencode
    return _iterencode(o, 0)
           ^^^^^^^^^^^^^^^^^
  File "/home/dominic-source/Projects/venv/lib/python3.11/site-packages/flask/json/provider.py", line 121, in _default
    raise TypeError(f"Object of type {type(o).__name__} is not JSON serializable")
TypeError: Object of type InstanceState is not JSON serializable
2024-05-10 15:46:11,105 - ERROR - Error occured:
Traceback (most recent call last):
  File "/home/dominic-source/Projects/Home_Deliverer/flask_server/views/v1/category.py", line 56, in get_category
    return jsonify(category.__dict__), 200
           ^^^^^^^^^^^^^^^^^^^^^^^^^^
  File "/home/dominic-source/Projects/venv/lib/python3.11/site-packages/flask/json/__init__.py", line 170, in jsonify
    return current_app.json.response(*args, **kwargs)  # type: ignore[return-value]
           ^^^^^^^^^^^^^^^^^^^^^^^^^^^^^^^^^^^^^^^^^^
  File "/home/dominic-source/Projects/venv/lib/python3.11/site-packages/flask/json/provider.py", line 214, in response
    f"{self.dumps(obj, **dump_args)}\n", mimetype=self.mimetype
       ^^^^^^^^^^^^^^^^^^^^^^^^^^^^
  File "/home/dominic-source/Projects/venv/lib/python3.11/site-packages/flask/json/provider.py", line 179, in dumps
    return json.dumps(obj, **kwargs)
           ^^^^^^^^^^^^^^^^^^^^^^^^^
  File "/usr/lib/python3.11/json/__init__.py", line 238, in dumps
    **kw).encode(obj)
          ^^^^^^^^^^^
  File "/usr/lib/python3.11/json/encoder.py", line 200, in encode
    chunks = self.iterencode(o, _one_shot=True)
             ^^^^^^^^^^^^^^^^^^^^^^^^^^^^^^^^^^
  File "/usr/lib/python3.11/json/encoder.py", line 258, in iterencode
    return _iterencode(o, 0)
           ^^^^^^^^^^^^^^^^^
  File "/home/dominic-source/Projects/venv/lib/python3.11/site-packages/flask/json/provider.py", line 121, in _default
    raise TypeError(f"Object of type {type(o).__name__} is not JSON serializable")
TypeError: Object of type InstanceState is not JSON serializable
2024-05-10 15:58:37,364 - ERROR - Error occured:
Traceback (most recent call last):
  File "/home/dominic-source/Projects/venv/lib/python3.11/site-packages/sqlalchemy/engine/base.py", line 1970, in _exec_single_context
    self.dialect.do_execute(
  File "/home/dominic-source/Projects/venv/lib/python3.11/site-packages/sqlalchemy/engine/default.py", line 924, in do_execute
    cursor.execute(statement, parameters)
sqlite3.IntegrityError: UNIQUE constraint failed: category.name

The above exception was the direct cause of the following exception:

Traceback (most recent call last):
  File "/home/dominic-source/Projects/Home_Deliverer/flask_server/views/v1/category.py", line 19, in create_category
    db.session.commit()
  File "/home/dominic-source/Projects/venv/lib/python3.11/site-packages/sqlalchemy/orm/scoping.py", line 597, in commit
    return self._proxied.commit()
           ^^^^^^^^^^^^^^^^^^^^^^
  File "/home/dominic-source/Projects/venv/lib/python3.11/site-packages/sqlalchemy/orm/session.py", line 1972, in commit
    trans.commit(_to_root=True)
  File "<string>", line 2, in commit
  File "/home/dominic-source/Projects/venv/lib/python3.11/site-packages/sqlalchemy/orm/state_changes.py", line 139, in _go
    ret_value = fn(self, *arg, **kw)
                ^^^^^^^^^^^^^^^^^^^^
  File "/home/dominic-source/Projects/venv/lib/python3.11/site-packages/sqlalchemy/orm/session.py", line 1257, in commit
    self._prepare_impl()
  File "<string>", line 2, in _prepare_impl
  File "/home/dominic-source/Projects/venv/lib/python3.11/site-packages/sqlalchemy/orm/state_changes.py", line 139, in _go
    ret_value = fn(self, *arg, **kw)
                ^^^^^^^^^^^^^^^^^^^^
  File "/home/dominic-source/Projects/venv/lib/python3.11/site-packages/sqlalchemy/orm/session.py", line 1232, in _prepare_impl
    self.session.flush()
  File "/home/dominic-source/Projects/venv/lib/python3.11/site-packages/sqlalchemy/orm/session.py", line 4296, in flush
    self._flush(objects)
  File "/home/dominic-source/Projects/venv/lib/python3.11/site-packages/sqlalchemy/orm/session.py", line 4431, in _flush
    with util.safe_reraise():
  File "/home/dominic-source/Projects/venv/lib/python3.11/site-packages/sqlalchemy/util/langhelpers.py", line 146, in __exit__
    raise exc_value.with_traceback(exc_tb)
  File "/home/dominic-source/Projects/venv/lib/python3.11/site-packages/sqlalchemy/orm/session.py", line 4392, in _flush
    flush_context.execute()
  File "/home/dominic-source/Projects/venv/lib/python3.11/site-packages/sqlalchemy/orm/unitofwork.py", line 466, in execute
    rec.execute(self)
  File "/home/dominic-source/Projects/venv/lib/python3.11/site-packages/sqlalchemy/orm/unitofwork.py", line 642, in execute
    util.preloaded.orm_persistence.save_obj(
  File "/home/dominic-source/Projects/venv/lib/python3.11/site-packages/sqlalchemy/orm/persistence.py", line 93, in save_obj
    _emit_insert_statements(
  File "/home/dominic-source/Projects/venv/lib/python3.11/site-packages/sqlalchemy/orm/persistence.py", line 1233, in _emit_insert_statements
    result = connection.execute(
             ^^^^^^^^^^^^^^^^^^^
  File "/home/dominic-source/Projects/venv/lib/python3.11/site-packages/sqlalchemy/engine/base.py", line 1421, in execute
    return meth(
           ^^^^^
  File "/home/dominic-source/Projects/venv/lib/python3.11/site-packages/sqlalchemy/sql/elements.py", line 514, in _execute_on_connection
    return connection._execute_clauseelement(
           ^^^^^^^^^^^^^^^^^^^^^^^^^^^^^^^^^^
  File "/home/dominic-source/Projects/venv/lib/python3.11/site-packages/sqlalchemy/engine/base.py", line 1643, in _execute_clauseelement
    ret = self._execute_context(
          ^^^^^^^^^^^^^^^^^^^^^^
  File "/home/dominic-source/Projects/venv/lib/python3.11/site-packages/sqlalchemy/engine/base.py", line 1849, in _execute_context
    return self._exec_single_context(
           ^^^^^^^^^^^^^^^^^^^^^^^^^^
  File "/home/dominic-source/Projects/venv/lib/python3.11/site-packages/sqlalchemy/engine/base.py", line 1989, in _exec_single_context
    self._handle_dbapi_exception(
  File "/home/dominic-source/Projects/venv/lib/python3.11/site-packages/sqlalchemy/engine/base.py", line 2356, in _handle_dbapi_exception
    raise sqlalchemy_exception.with_traceback(exc_info[2]) from e
  File "/home/dominic-source/Projects/venv/lib/python3.11/site-packages/sqlalchemy/engine/base.py", line 1970, in _exec_single_context
    self.dialect.do_execute(
  File "/home/dominic-source/Projects/venv/lib/python3.11/site-packages/sqlalchemy/engine/default.py", line 924, in do_execute
    cursor.execute(statement, parameters)
sqlalchemy.exc.IntegrityError: (sqlite3.IntegrityError) UNIQUE constraint failed: category.name
[SQL: INSERT INTO category (name) VALUES (?)]
[parameters: ('Consumable Products | Food & Beverages | Staples (Rice, Flour, Pasta)',)]
(Background on this error at: https://sqlalche.me/e/20/gkpj)
2024-05-10 15:59:23,418 - ERROR - Error occured:
Traceback (most recent call last):
  File "/home/dominic-source/Projects/venv/lib/python3.11/site-packages/sqlalchemy/engine/base.py", line 1970, in _exec_single_context
    self.dialect.do_execute(
  File "/home/dominic-source/Projects/venv/lib/python3.11/site-packages/sqlalchemy/engine/default.py", line 924, in do_execute
    cursor.execute(statement, parameters)
sqlite3.IntegrityError: UNIQUE constraint failed: category.name

The above exception was the direct cause of the following exception:

Traceback (most recent call last):
  File "/home/dominic-source/Projects/Home_Deliverer/flask_server/views/v1/category.py", line 19, in create_category
    db.session.commit()
  File "/home/dominic-source/Projects/venv/lib/python3.11/site-packages/sqlalchemy/orm/scoping.py", line 597, in commit
    return self._proxied.commit()
           ^^^^^^^^^^^^^^^^^^^^^^
  File "/home/dominic-source/Projects/venv/lib/python3.11/site-packages/sqlalchemy/orm/session.py", line 1972, in commit
    trans.commit(_to_root=True)
  File "<string>", line 2, in commit
  File "/home/dominic-source/Projects/venv/lib/python3.11/site-packages/sqlalchemy/orm/state_changes.py", line 139, in _go
    ret_value = fn(self, *arg, **kw)
                ^^^^^^^^^^^^^^^^^^^^
  File "/home/dominic-source/Projects/venv/lib/python3.11/site-packages/sqlalchemy/orm/session.py", line 1257, in commit
    self._prepare_impl()
  File "<string>", line 2, in _prepare_impl
  File "/home/dominic-source/Projects/venv/lib/python3.11/site-packages/sqlalchemy/orm/state_changes.py", line 139, in _go
    ret_value = fn(self, *arg, **kw)
                ^^^^^^^^^^^^^^^^^^^^
  File "/home/dominic-source/Projects/venv/lib/python3.11/site-packages/sqlalchemy/orm/session.py", line 1232, in _prepare_impl
    self.session.flush()
  File "/home/dominic-source/Projects/venv/lib/python3.11/site-packages/sqlalchemy/orm/session.py", line 4296, in flush
    self._flush(objects)
  File "/home/dominic-source/Projects/venv/lib/python3.11/site-packages/sqlalchemy/orm/session.py", line 4431, in _flush
    with util.safe_reraise():
  File "/home/dominic-source/Projects/venv/lib/python3.11/site-packages/sqlalchemy/util/langhelpers.py", line 146, in __exit__
    raise exc_value.with_traceback(exc_tb)
  File "/home/dominic-source/Projects/venv/lib/python3.11/site-packages/sqlalchemy/orm/session.py", line 4392, in _flush
    flush_context.execute()
  File "/home/dominic-source/Projects/venv/lib/python3.11/site-packages/sqlalchemy/orm/unitofwork.py", line 466, in execute
    rec.execute(self)
  File "/home/dominic-source/Projects/venv/lib/python3.11/site-packages/sqlalchemy/orm/unitofwork.py", line 642, in execute
    util.preloaded.orm_persistence.save_obj(
  File "/home/dominic-source/Projects/venv/lib/python3.11/site-packages/sqlalchemy/orm/persistence.py", line 93, in save_obj
    _emit_insert_statements(
  File "/home/dominic-source/Projects/venv/lib/python3.11/site-packages/sqlalchemy/orm/persistence.py", line 1233, in _emit_insert_statements
    result = connection.execute(
             ^^^^^^^^^^^^^^^^^^^
  File "/home/dominic-source/Projects/venv/lib/python3.11/site-packages/sqlalchemy/engine/base.py", line 1421, in execute
    return meth(
           ^^^^^
  File "/home/dominic-source/Projects/venv/lib/python3.11/site-packages/sqlalchemy/sql/elements.py", line 514, in _execute_on_connection
    return connection._execute_clauseelement(
           ^^^^^^^^^^^^^^^^^^^^^^^^^^^^^^^^^^
  File "/home/dominic-source/Projects/venv/lib/python3.11/site-packages/sqlalchemy/engine/base.py", line 1643, in _execute_clauseelement
    ret = self._execute_context(
          ^^^^^^^^^^^^^^^^^^^^^^
  File "/home/dominic-source/Projects/venv/lib/python3.11/site-packages/sqlalchemy/engine/base.py", line 1849, in _execute_context
    return self._exec_single_context(
           ^^^^^^^^^^^^^^^^^^^^^^^^^^
  File "/home/dominic-source/Projects/venv/lib/python3.11/site-packages/sqlalchemy/engine/base.py", line 1989, in _exec_single_context
    self._handle_dbapi_exception(
  File "/home/dominic-source/Projects/venv/lib/python3.11/site-packages/sqlalchemy/engine/base.py", line 2356, in _handle_dbapi_exception
    raise sqlalchemy_exception.with_traceback(exc_info[2]) from e
  File "/home/dominic-source/Projects/venv/lib/python3.11/site-packages/sqlalchemy/engine/base.py", line 1970, in _exec_single_context
    self.dialect.do_execute(
  File "/home/dominic-source/Projects/venv/lib/python3.11/site-packages/sqlalchemy/engine/default.py", line 924, in do_execute
    cursor.execute(statement, parameters)
sqlalchemy.exc.IntegrityError: (sqlite3.IntegrityError) UNIQUE constraint failed: category.name
[SQL: INSERT INTO category (name) VALUES (?)]
[parameters: ('Consumable Products | Food & Beverages | Staples (Rice, Flour, Pasta)',)]
(Background on this error at: https://sqlalche.me/e/20/gkpj)
2024-05-10 15:59:35,824 - ERROR - Error occured:
Traceback (most recent call last):
  File "/home/dominic-source/Projects/venv/lib/python3.11/site-packages/sqlalchemy/engine/base.py", line 1970, in _exec_single_context
    self.dialect.do_execute(
  File "/home/dominic-source/Projects/venv/lib/python3.11/site-packages/sqlalchemy/engine/default.py", line 924, in do_execute
    cursor.execute(statement, parameters)
sqlite3.IntegrityError: UNIQUE constraint failed: category.name

The above exception was the direct cause of the following exception:

Traceback (most recent call last):
  File "/home/dominic-source/Projects/Home_Deliverer/flask_server/views/v1/category.py", line 19, in create_category
    db.session.commit()
  File "/home/dominic-source/Projects/venv/lib/python3.11/site-packages/sqlalchemy/orm/scoping.py", line 597, in commit
    return self._proxied.commit()
           ^^^^^^^^^^^^^^^^^^^^^^
  File "/home/dominic-source/Projects/venv/lib/python3.11/site-packages/sqlalchemy/orm/session.py", line 1972, in commit
    trans.commit(_to_root=True)
  File "<string>", line 2, in commit
  File "/home/dominic-source/Projects/venv/lib/python3.11/site-packages/sqlalchemy/orm/state_changes.py", line 139, in _go
    ret_value = fn(self, *arg, **kw)
                ^^^^^^^^^^^^^^^^^^^^
  File "/home/dominic-source/Projects/venv/lib/python3.11/site-packages/sqlalchemy/orm/session.py", line 1257, in commit
    self._prepare_impl()
  File "<string>", line 2, in _prepare_impl
  File "/home/dominic-source/Projects/venv/lib/python3.11/site-packages/sqlalchemy/orm/state_changes.py", line 139, in _go
    ret_value = fn(self, *arg, **kw)
                ^^^^^^^^^^^^^^^^^^^^
  File "/home/dominic-source/Projects/venv/lib/python3.11/site-packages/sqlalchemy/orm/session.py", line 1232, in _prepare_impl
    self.session.flush()
  File "/home/dominic-source/Projects/venv/lib/python3.11/site-packages/sqlalchemy/orm/session.py", line 4296, in flush
    self._flush(objects)
  File "/home/dominic-source/Projects/venv/lib/python3.11/site-packages/sqlalchemy/orm/session.py", line 4431, in _flush
    with util.safe_reraise():
  File "/home/dominic-source/Projects/venv/lib/python3.11/site-packages/sqlalchemy/util/langhelpers.py", line 146, in __exit__
    raise exc_value.with_traceback(exc_tb)
  File "/home/dominic-source/Projects/venv/lib/python3.11/site-packages/sqlalchemy/orm/session.py", line 4392, in _flush
    flush_context.execute()
  File "/home/dominic-source/Projects/venv/lib/python3.11/site-packages/sqlalchemy/orm/unitofwork.py", line 466, in execute
    rec.execute(self)
  File "/home/dominic-source/Projects/venv/lib/python3.11/site-packages/sqlalchemy/orm/unitofwork.py", line 642, in execute
    util.preloaded.orm_persistence.save_obj(
  File "/home/dominic-source/Projects/venv/lib/python3.11/site-packages/sqlalchemy/orm/persistence.py", line 93, in save_obj
    _emit_insert_statements(
  File "/home/dominic-source/Projects/venv/lib/python3.11/site-packages/sqlalchemy/orm/persistence.py", line 1233, in _emit_insert_statements
    result = connection.execute(
             ^^^^^^^^^^^^^^^^^^^
  File "/home/dominic-source/Projects/venv/lib/python3.11/site-packages/sqlalchemy/engine/base.py", line 1421, in execute
    return meth(
           ^^^^^
  File "/home/dominic-source/Projects/venv/lib/python3.11/site-packages/sqlalchemy/sql/elements.py", line 514, in _execute_on_connection
    return connection._execute_clauseelement(
           ^^^^^^^^^^^^^^^^^^^^^^^^^^^^^^^^^^
  File "/home/dominic-source/Projects/venv/lib/python3.11/site-packages/sqlalchemy/engine/base.py", line 1643, in _execute_clauseelement
    ret = self._execute_context(
          ^^^^^^^^^^^^^^^^^^^^^^
  File "/home/dominic-source/Projects/venv/lib/python3.11/site-packages/sqlalchemy/engine/base.py", line 1849, in _execute_context
    return self._exec_single_context(
           ^^^^^^^^^^^^^^^^^^^^^^^^^^
  File "/home/dominic-source/Projects/venv/lib/python3.11/site-packages/sqlalchemy/engine/base.py", line 1989, in _exec_single_context
    self._handle_dbapi_exception(
  File "/home/dominic-source/Projects/venv/lib/python3.11/site-packages/sqlalchemy/engine/base.py", line 2356, in _handle_dbapi_exception
    raise sqlalchemy_exception.with_traceback(exc_info[2]) from e
  File "/home/dominic-source/Projects/venv/lib/python3.11/site-packages/sqlalchemy/engine/base.py", line 1970, in _exec_single_context
    self.dialect.do_execute(
  File "/home/dominic-source/Projects/venv/lib/python3.11/site-packages/sqlalchemy/engine/default.py", line 924, in do_execute
    cursor.execute(statement, parameters)
sqlalchemy.exc.IntegrityError: (sqlite3.IntegrityError) UNIQUE constraint failed: category.name
[SQL: INSERT INTO category (name) VALUES (?)]
[parameters: ('Consumable Products | Food & Beverages | Staples (Rice, Flour, Pasta)',)]
(Background on this error at: https://sqlalche.me/e/20/gkpj)
2024-05-10 16:13:36,372 - ERROR - Error occured:
Traceback (most recent call last):
  File "/home/dominic-source/Projects/venv/lib/python3.11/site-packages/sqlalchemy/engine/base.py", line 1970, in _exec_single_context
    self.dialect.do_execute(
  File "/home/dominic-source/Projects/venv/lib/python3.11/site-packages/sqlalchemy/engine/default.py", line 924, in do_execute
    cursor.execute(statement, parameters)
sqlite3.IntegrityError: UNIQUE constraint failed: category.name

The above exception was the direct cause of the following exception:

Traceback (most recent call last):
  File "/home/dominic-source/Projects/Home_Deliverer/flask_server/views/v1/category.py", line 37, in create_category
    db.session.commit()
  File "/home/dominic-source/Projects/venv/lib/python3.11/site-packages/sqlalchemy/orm/scoping.py", line 597, in commit
    return self._proxied.commit()
           ^^^^^^^^^^^^^^^^^^^^^^
  File "/home/dominic-source/Projects/venv/lib/python3.11/site-packages/sqlalchemy/orm/session.py", line 1972, in commit
    trans.commit(_to_root=True)
  File "<string>", line 2, in commit
  File "/home/dominic-source/Projects/venv/lib/python3.11/site-packages/sqlalchemy/orm/state_changes.py", line 139, in _go
    ret_value = fn(self, *arg, **kw)
                ^^^^^^^^^^^^^^^^^^^^
  File "/home/dominic-source/Projects/venv/lib/python3.11/site-packages/sqlalchemy/orm/session.py", line 1257, in commit
    self._prepare_impl()
  File "<string>", line 2, in _prepare_impl
  File "/home/dominic-source/Projects/venv/lib/python3.11/site-packages/sqlalchemy/orm/state_changes.py", line 139, in _go
    ret_value = fn(self, *arg, **kw)
                ^^^^^^^^^^^^^^^^^^^^
  File "/home/dominic-source/Projects/venv/lib/python3.11/site-packages/sqlalchemy/orm/session.py", line 1232, in _prepare_impl
    self.session.flush()
  File "/home/dominic-source/Projects/venv/lib/python3.11/site-packages/sqlalchemy/orm/session.py", line 4296, in flush
    self._flush(objects)
  File "/home/dominic-source/Projects/venv/lib/python3.11/site-packages/sqlalchemy/orm/session.py", line 4431, in _flush
    with util.safe_reraise():
  File "/home/dominic-source/Projects/venv/lib/python3.11/site-packages/sqlalchemy/util/langhelpers.py", line 146, in __exit__
    raise exc_value.with_traceback(exc_tb)
  File "/home/dominic-source/Projects/venv/lib/python3.11/site-packages/sqlalchemy/orm/session.py", line 4392, in _flush
    flush_context.execute()
  File "/home/dominic-source/Projects/venv/lib/python3.11/site-packages/sqlalchemy/orm/unitofwork.py", line 466, in execute
    rec.execute(self)
  File "/home/dominic-source/Projects/venv/lib/python3.11/site-packages/sqlalchemy/orm/unitofwork.py", line 642, in execute
    util.preloaded.orm_persistence.save_obj(
  File "/home/dominic-source/Projects/venv/lib/python3.11/site-packages/sqlalchemy/orm/persistence.py", line 93, in save_obj
    _emit_insert_statements(
  File "/home/dominic-source/Projects/venv/lib/python3.11/site-packages/sqlalchemy/orm/persistence.py", line 1233, in _emit_insert_statements
    result = connection.execute(
             ^^^^^^^^^^^^^^^^^^^
  File "/home/dominic-source/Projects/venv/lib/python3.11/site-packages/sqlalchemy/engine/base.py", line 1421, in execute
    return meth(
           ^^^^^
  File "/home/dominic-source/Projects/venv/lib/python3.11/site-packages/sqlalchemy/sql/elements.py", line 514, in _execute_on_connection
    return connection._execute_clauseelement(
           ^^^^^^^^^^^^^^^^^^^^^^^^^^^^^^^^^^
  File "/home/dominic-source/Projects/venv/lib/python3.11/site-packages/sqlalchemy/engine/base.py", line 1643, in _execute_clauseelement
    ret = self._execute_context(
          ^^^^^^^^^^^^^^^^^^^^^^
  File "/home/dominic-source/Projects/venv/lib/python3.11/site-packages/sqlalchemy/engine/base.py", line 1849, in _execute_context
    return self._exec_single_context(
           ^^^^^^^^^^^^^^^^^^^^^^^^^^
  File "/home/dominic-source/Projects/venv/lib/python3.11/site-packages/sqlalchemy/engine/base.py", line 1989, in _exec_single_context
    self._handle_dbapi_exception(
  File "/home/dominic-source/Projects/venv/lib/python3.11/site-packages/sqlalchemy/engine/base.py", line 2356, in _handle_dbapi_exception
    raise sqlalchemy_exception.with_traceback(exc_info[2]) from e
  File "/home/dominic-source/Projects/venv/lib/python3.11/site-packages/sqlalchemy/engine/base.py", line 1970, in _exec_single_context
    self.dialect.do_execute(
  File "/home/dominic-source/Projects/venv/lib/python3.11/site-packages/sqlalchemy/engine/default.py", line 924, in do_execute
    cursor.execute(statement, parameters)
sqlalchemy.exc.IntegrityError: (sqlite3.IntegrityError) UNIQUE constraint failed: category.name
[SQL: INSERT INTO category (name) VALUES (?)]
[parameters: ('Consumable Products | Food & Beverages | Staples (Rice, Flour, Pasta)',)]
(Background on this error at: https://sqlalche.me/e/20/gkpj)
2024-05-10 16:14:17,657 - ERROR - Error occured:
Traceback (most recent call last):
  File "/home/dominic-source/Projects/venv/lib/python3.11/site-packages/sqlalchemy/engine/base.py", line 1970, in _exec_single_context
    self.dialect.do_execute(
  File "/home/dominic-source/Projects/venv/lib/python3.11/site-packages/sqlalchemy/engine/default.py", line 924, in do_execute
    cursor.execute(statement, parameters)
sqlite3.IntegrityError: UNIQUE constraint failed: category.name

The above exception was the direct cause of the following exception:

Traceback (most recent call last):
  File "/home/dominic-source/Projects/Home_Deliverer/flask_server/views/v1/category.py", line 37, in create_category
    db.session.commit()
  File "/home/dominic-source/Projects/venv/lib/python3.11/site-packages/sqlalchemy/orm/scoping.py", line 597, in commit
    return self._proxied.commit()
           ^^^^^^^^^^^^^^^^^^^^^^
  File "/home/dominic-source/Projects/venv/lib/python3.11/site-packages/sqlalchemy/orm/session.py", line 1972, in commit
    trans.commit(_to_root=True)
  File "<string>", line 2, in commit
  File "/home/dominic-source/Projects/venv/lib/python3.11/site-packages/sqlalchemy/orm/state_changes.py", line 139, in _go
    ret_value = fn(self, *arg, **kw)
                ^^^^^^^^^^^^^^^^^^^^
  File "/home/dominic-source/Projects/venv/lib/python3.11/site-packages/sqlalchemy/orm/session.py", line 1257, in commit
    self._prepare_impl()
  File "<string>", line 2, in _prepare_impl
  File "/home/dominic-source/Projects/venv/lib/python3.11/site-packages/sqlalchemy/orm/state_changes.py", line 139, in _go
    ret_value = fn(self, *arg, **kw)
                ^^^^^^^^^^^^^^^^^^^^
  File "/home/dominic-source/Projects/venv/lib/python3.11/site-packages/sqlalchemy/orm/session.py", line 1232, in _prepare_impl
    self.session.flush()
  File "/home/dominic-source/Projects/venv/lib/python3.11/site-packages/sqlalchemy/orm/session.py", line 4296, in flush
    self._flush(objects)
  File "/home/dominic-source/Projects/venv/lib/python3.11/site-packages/sqlalchemy/orm/session.py", line 4431, in _flush
    with util.safe_reraise():
  File "/home/dominic-source/Projects/venv/lib/python3.11/site-packages/sqlalchemy/util/langhelpers.py", line 146, in __exit__
    raise exc_value.with_traceback(exc_tb)
  File "/home/dominic-source/Projects/venv/lib/python3.11/site-packages/sqlalchemy/orm/session.py", line 4392, in _flush
    flush_context.execute()
  File "/home/dominic-source/Projects/venv/lib/python3.11/site-packages/sqlalchemy/orm/unitofwork.py", line 466, in execute
    rec.execute(self)
  File "/home/dominic-source/Projects/venv/lib/python3.11/site-packages/sqlalchemy/orm/unitofwork.py", line 642, in execute
    util.preloaded.orm_persistence.save_obj(
  File "/home/dominic-source/Projects/venv/lib/python3.11/site-packages/sqlalchemy/orm/persistence.py", line 93, in save_obj
    _emit_insert_statements(
  File "/home/dominic-source/Projects/venv/lib/python3.11/site-packages/sqlalchemy/orm/persistence.py", line 1233, in _emit_insert_statements
    result = connection.execute(
             ^^^^^^^^^^^^^^^^^^^
  File "/home/dominic-source/Projects/venv/lib/python3.11/site-packages/sqlalchemy/engine/base.py", line 1421, in execute
    return meth(
           ^^^^^
  File "/home/dominic-source/Projects/venv/lib/python3.11/site-packages/sqlalchemy/sql/elements.py", line 514, in _execute_on_connection
    return connection._execute_clauseelement(
           ^^^^^^^^^^^^^^^^^^^^^^^^^^^^^^^^^^
  File "/home/dominic-source/Projects/venv/lib/python3.11/site-packages/sqlalchemy/engine/base.py", line 1643, in _execute_clauseelement
    ret = self._execute_context(
          ^^^^^^^^^^^^^^^^^^^^^^
  File "/home/dominic-source/Projects/venv/lib/python3.11/site-packages/sqlalchemy/engine/base.py", line 1849, in _execute_context
    return self._exec_single_context(
           ^^^^^^^^^^^^^^^^^^^^^^^^^^
  File "/home/dominic-source/Projects/venv/lib/python3.11/site-packages/sqlalchemy/engine/base.py", line 1989, in _exec_single_context
    self._handle_dbapi_exception(
  File "/home/dominic-source/Projects/venv/lib/python3.11/site-packages/sqlalchemy/engine/base.py", line 2356, in _handle_dbapi_exception
    raise sqlalchemy_exception.with_traceback(exc_info[2]) from e
  File "/home/dominic-source/Projects/venv/lib/python3.11/site-packages/sqlalchemy/engine/base.py", line 1970, in _exec_single_context
    self.dialect.do_execute(
  File "/home/dominic-source/Projects/venv/lib/python3.11/site-packages/sqlalchemy/engine/default.py", line 924, in do_execute
    cursor.execute(statement, parameters)
sqlalchemy.exc.IntegrityError: (sqlite3.IntegrityError) UNIQUE constraint failed: category.name
[SQL: INSERT INTO category (name) VALUES (?)]
[parameters: ('Consumable Products | Food & Beverages | Staples (Rice, Flour, Pasta)',)]
(Background on this error at: https://sqlalche.me/e/20/gkpj)
